Workbook

Sheet Frasco 50 ML y  8ml
B2: Frances 10 Libras
B3: Materia Prima | C3: Formula % | D3: mililitros | E3: frasco | F3: Conversion (lb) | G3: Costo Q. por ml o Unidad empeado | H3: Costo *ml
B4: Fixa Plus | C4: 0.1 | D4: 10 | F4: =D4+E4 -> 10 | G4: =IFERROR(VLOOKUP(B4,'MP perfume'!$A$6:$F$32,6,FALSE),0) -> 0.018254288 | H4: =F4*G4 -> 0.18254288
B5: propilenglicol | C5: 0.6 | D5: 60 | F5: =D5+E5 -> 60 | G5: =IFERROR(VLOOKUP(B5,'MP perfume'!$A$6:$F$32,6,FALSE),0) -> 0.022454623 | H5: =F5*G5 -> 1.3472774
B6: Fragancia Arabe | C6: 0.3 | D6: 30 | F6: =D6+E6 -> 30 | G6: =IFERROR(VLOOKUP(B6,'MP perfume'!$A$6:$F$32,6,FALSE),0) -> 0.93333333 | H6: =F6*G6 -> 28
B7: Frasco 50 Ml | E7: 1 | F7: =D7+E7 -> 1 | G7: =IFERROR(VLOOKUP(B7,'MP perfume'!$A$6:$F$32,6,FALSE),0) -> 9.85 | H7: =F7*G7 -> 9.85
B8: Frasco Individual | E8: 6 | F8: =D8+E8 -> 6 | G8: =IFERROR(VLOOKUP(B8,'MP perfume'!$A$6:$F$32,6,FALSE),0) -> 5.5 | H8: =F8*G8 -> 33
F9: =D9+E9 -> 0 | G9: =IFERROR(VLOOKUP(B9,'MP perfume'!$A$6:$F$32,6,FALSE),0) -> 0 | H9: =F9*G9 -> 0
F10: =D10+E10 -> 0 | G10: =IFERROR(VLOOKUP(B10,'MP perfume'!$A$6:$F$32,6,FALSE),0) -> 0 | H10: =F10*G10 -> 0
F11: =D11+E11 -> 0 | G11: =IFERROR(VLOOKUP(B11,'MP perfume'!$A$6:$F$32,6,FALSE),0) -> 0 | H11: =F11*G11 -> 0
F12: =D12+E12 -> 0 | G12: =IFERROR(VLOOKUP(B12,'MP perfume'!$A$6:$F$32,6,FALSE),0) -> 0 | H12: =F12*G12 -> 0
F13: =D13+E13 -> 0 | G13: =IFERROR(VLOOKUP(B13,'MP perfume'!$A$6:$F$32,6,FALSE),0) -> 0 | H13: =F13*G13 -> 0
B14: Total | D14: =SUM(D4:D13) -> 100 | E14: =SUM(E4:E13) -> 7 | F14: =SUM(F4:F13) -> 107 | G14: =SUM(G4:G13) -> 16.324042 | H14: =SUM(H4:H13) -> 72.37982
C16: Con esta fórmiula puedo producir | D16: 1 | E16: Fragancias de 50 ML
C17: Costo Prod. | D17: =SUM(H4:H6)/2+H7 -> 24.61491
C18: Precio Venta | D18: 60 | G18: =SUM(H4:H6)/100 -> 0.2952982 | J18: 15 | K18: =25 -> 25 | L18: =K18*J18 -> 375
C19: Con esta fórmiula puedo producir | D19: 6 | E19: Fragancia Individual | G19: =G18*50 -> 14.76491 | J19: 1 | K19: 25 | L19: =K19*J19 -> 25
C20: Costo Prod. | D20: =G19+H8 -> 47.76491 | E20: =D20/D19 -> 7.9608184
C21: Precio Venta | D21: 150 | E21: 25 | F21: =E21-E20 -> 17.039182
C22: Costo Total Diario | E22: =D20+D17 -> 72.37982
C23: Venta Total Diaria | E23: =D21+D18 -> 210
C24: Ganancia Diaria | E24: =E23-E22 -> 137.62018
C25: % de ganancia | E25: =E24/E22 -> 1.9013612

Sheet Frasco 100 ML
B2: Frances 10 Libras
B3: Materia Prima | C3: Formula % | D3: mililitros | E3: frasco | F3: Conversion (lb) | G3: Costo Q. por ml o Unidad empeado | H3: Costo *Lb
B4: Fixa Plus | C4: 0.1 | D4: 10 | F4: =IFERROR(D4+E4/16,"") -> 10 | G4: =IFERROR(VLOOKUP(B4,'MP perfume'!$A$6:$F$32,6,FALSE),0) -> 0.018254288 | H4: =F4*G4 -> 0.18254288
B5: propilenglicol | C5: 0.6 | D5: 60 | F5: =IFERROR(D5+E5/16,"") -> 60 | G5: =IFERROR(VLOOKUP(B5,'MP perfume'!$A$6:$F$32,6,FALSE),0) -> 0.022454623 | H5: =F5*G5 -> 1.3472774
B6: Fragancia Arabe | C6: 0.3 | D6: 30 | F6: =IFERROR(D6+E6/16,"") -> 30 | G6: =IFERROR(VLOOKUP(B6,'MP perfume'!$A$6:$F$32,6,FALSE),0) -> 0.93333333 | H6: =F6*G6 -> 28
B7: Frasco 100 ML | E7: 1 | F7: =E7 -> 1 | G7: =IFERROR(VLOOKUP(B7,'MP perfume'!$A$6:$F$32,6,FALSE),0) -> 12.5 | H7: =F7*G7 -> 12.5
F8: =IFERROR(D8+E8/16,"") -> 0 | G8: =IFERROR(VLOOKUP(B8,'MP perfume'!$A$6:$F$32,6,FALSE),0) -> 0 | H8: =F8*G8 -> 0
F9: =IFERROR(D9+E9/16,"") -> 0 | G9: =IFERROR(VLOOKUP(B9,'MP perfume'!$A$6:$F$32,6,FALSE),0) -> 0 | H9: =F9*G9 -> 0
F10: =IFERROR(D10+E10/16,"") -> 0 | G10: =IFERROR(VLOOKUP(B10,'MP perfume'!$A$6:$F$32,6,FALSE),0) -> 0 | H10: =F10*G10 -> 0
F11: =IFERROR(D11+E11/16,"") -> 0 | G11: =IFERROR(VLOOKUP(B11,'MP perfume'!$A$6:$F$32,6,FALSE),0) -> 0 | H11: =F11*G11 -> 0
F12: =IFERROR(D12+E12/16,"") -> 0 | G12: =IFERROR(VLOOKUP(B12,'MP perfume'!$A$6:$F$32,6,FALSE),0) -> 0 | H12: =F12*G12 -> 0
F13: =IFERROR(D13+E13/16," ") -> 0 | G13: =IFERROR(VLOOKUP(B13,'MP perfume'!$A$6:$F$32,6,FALSE),0) -> 0 | H13: =F13*G13 -> 0
B14: Total | D14: =SUM(D4:D13) -> 100 | E14: =SUM(E4:E13) -> 1 | F14: =SUM(F4:F13) -> 101 | G14: =SUM(G4:G13) -> 13.474042 | H14: =SUM(H4:H13) -> 42.02982
C16: Con esta fórmiula puedo producir | D16: 1 | E16: Fragancias de 50 ML
C17: Costo Prod. | D17: =H14/D16 -> 42.02982
C18: Precio Venta | D18: 120
C22: Costo Total Diario | E22: =H14*1.36 -> 57.160556
C23: Venta Total Diaria | E23: =D18*D16 -> 120
C24: Ganancia Diaria | E24: =E23-E22 -> 62.839444
C25: % de ganancia | E25: =E24/E22 -> 1.0993498

Sheet Frasco 50 ML
B2: Frances 10 Libras
B3: Materia Prima | C3: Formula % | D3: mililitros | E3: frasco | F3: Conversion (lb) | G3: Costo Q. por ml o Unidad empeado | H3: Costo *Lb
B4: Fixa Plus | C4: 0.1 | D4: 10 | F4: =IFERROR(D4+E4/16,"") -> 10 | G4: =IFERROR(VLOOKUP(B4,'MP perfume'!$A$6:$F$32,6,FALSE),0) -> 0.018254288 | H4: =F4*G4 -> 0.18254288
B5: propilenglicol | C5: 0.6 | D5: 60 | F5: =IFERROR(D5+E5/16,"") -> 60 | G5: =IFERROR(VLOOKUP(B5,'MP perfume'!$A$6:$F$32,6,FALSE),0) -> 0.022454623 | H5: =F5*G5 -> 1.3472774
B6: Fragancia Arabe | C6: 0.3 | D6: 30 | F6: =IFERROR(D6+E6/16,"") -> 30 | G6: =IFERROR(VLOOKUP(B6,'MP perfume'!$A$6:$F$32,6,FALSE),0) -> 0.93333333 | H6: =F6*G6 -> 28
B7: Frasco 50 Ml | E7: 2 | F7: =E7 -> 2 | G7: =IFERROR(VLOOKUP(B7,'MP perfume'!$A$6:$F$32,6,FALSE),0) -> 9.85 | H7: =F7*G7 -> 19.7
F8: =IFERROR(D8+E8/16,"") -> 0 | G8: =IFERROR(VLOOKUP(B8,'MP perfume'!$A$6:$F$32,6,FALSE),0) -> 0 | H8: =F8*G8 -> 0
F9: =IFERROR(D9+E9/16,"") -> 0 | G9: =IFERROR(VLOOKUP(B9,'MP perfume'!$A$6:$F$32,6,FALSE),0) -> 0 | H9: =F9*G9 -> 0
F10: =IFERROR(D10+E10/16,"") -> 0 | G10: =IFERROR(VLOOKUP(B10,'MP perfume'!$A$6:$F$32,6,FALSE),0) -> 0 | H10: =F10*G10 -> 0
F11: =IFERROR(D11+E11/16,"") -> 0 | G11: =IFERROR(VLOOKUP(B11,'MP perfume'!$A$6:$F$32,6,FALSE),0) -> 0 | H11: =F11*G11 -> 0
F12: =IFERROR(D12+E12/16,"") -> 0 | G12: =IFERROR(VLOOKUP(B12,'MP perfume'!$A$6:$F$32,6,FALSE),0) -> 0 | H12: =F12*G12 -> 0
F13: =IFERROR(D13+E13/16," ") -> 0 | G13: =IFERROR(VLOOKUP(B13,'MP perfume'!$A$6:$F$32,6,FALSE),0) -> 0 | H13: =F13*G13 -> 0
B14: Total | D14: =SUM(D4:D13) -> 100 | E14: =SUM(E4:E13) -> 2 | F14: =SUM(F4:F13) -> 102 | G14: =SUM(G4:G13) -> 10.824042 | H14: =SUM(H4:H13) -> 49.22982
C16: Con esta fórmiula puedo producir | D16: 2 | E16: Fragancias de 50 ML
C17: Costo Prod. | D17: =H14/D16 -> 24.61491
C18: Precio Venta | D18: 60
C22: Costo Total Diario | E22: =H14*1.36 -> 66.952556
C23: Venta Total Diaria | E23: =D18*D16 -> 120
C24: Ganancia Diaria | E24: =E23-E22 -> 53.047444
C25: % de ganancia | E25: =E24/E22 -> 0.79231396

Sheet MP perfume
A1: Seguimiento del mercado - Materias Primas y Materiales de Empaque
A4: Materias Primas
A5: Nombre | B5: Presentación | C5: Cantidad | D5: Unidad | E5: Precio Q. | F5: Precio Q por LB o Unidad | G5: Antes
A6: Fixa Plus | B6: Galon | C6: 3785.412 | D6: Mililitro | E6: 69.1 | F6: =E6/C6 -> 0.018254288
A7: propilenglicol | B7: Galon | C7: 3785.412 | D7: MIlilitro | E7: 85 | F7: =E7/C7 -> 0.022454623
A8: Frasco 50 Ml | B8: Frasco | C8: 1 | D8: Unidad | E8: 9.85 | F8: =E8/C8 -> 9.85
A9: Frasco 100 ML | B9: Frasco | C9: 1 | D9: Unidad | E9: 12.5 | F9: =E9/C9 -> 12.5
A10: Frasco Individual | B10: Frasco | C10: 24 | D10: Unidad | E10: =24*5.5 -> 132 | F10: =E10/C10 -> 5.5
A11: Fragancia | B11: Bote | C11: 30 | D11: Mililitros | E11: 25 | F11: =E11/C11 -> 0.83333333
A12: Fragancia Arabe | B12: Bote | C12: 30 | D12: Mililitros | E12: 28 | F12: =E12/C12 -> 0.93333333
A34: Materiales de empaque
A35: Tipo | B35: Dimension (cm) | C35: Cantidad | D35: Valor Q. | E35: Costo Unitario
A36: Bolsa 2 Lb | B36: 16X20 | C36: 500 | D36: 9 | E36: =D36/C36 -> 0.018
A37: Bolsa 5 Lb | B37: 23X20 | C37: 500 | D37: 12 | E37: =D37/C37 -> 0.024
A38: Bolsa Gabachita | B38: Gabachita | C38: 300 | D38: 20 | E38: =D38/C38 -> 0.066666667
A39: Funda cubiletes | B39: #2 | C39: 10000 | D39: 260 | E39: =D39/C39 -> 0.026
A40: Funda Cub. Blanco | B40: #5 | C40: 10000 | D40: 330 | E40: =D40/C40 -> 0.033
A41: Funda Cub. Rojo | B41: #5 | C41: 10000 | D41: 415 | E41: =D41/C41 -> 0.0415

Sheet MP Pan
A1: Seguimiento del mercado - Materias Primas y Materiales de Empaque
A4: Materias Primas
A5: Nombre | B5: Presentación | C5: Cantidad | D5: Unidad | E5: Precio Q. | F5: Precio Q por LB o Unidad | G5: Antes
A6: Harina Suave | B6: Saco | C6: 100 | D6: lb | E6: 285 | F6: =E6/C6 -> 2.85 | G6: 3.14 | H6: =G6-F6 -> 0.29
A7: Harina Suave Flo | B7: Saco | C7: 50 | D7: Lb | E7: =7.5*50 -> 375 | F7: =E7/C7 -> 7.5
A8: Harina Dura | B8: saco | C8: 100 | D8: lb | E8: 285 | F8: =E8/C8 -> 2.85 | G8: 3.12 | H8: =G8-F8 -> 0.27
A9: Salpor | B9: libras | C9: 1 | D9: lb | E9: 13 | F9: =E9/C9 -> 13 | G9: 15
A10: Azucar | B10: Saco | C10: 100 | D10: lb | E10: 450 | F10: =E10/C10 -> 4.5 | G10: 3.9 | H10: =G10-F10 -> -0.6
A11: Levadura | B11: caja | C11: 10 | D11: Unidad | E11: 115 | F11: =E11/C11 -> 11.5 | G11: 11 | H11: =G11-F11 -> -0.5
A12: Royal | B12: saco | C12: 5 | D12: lb | E12: 23 | F12: =E12/C12 -> 4.6 | G12: 23 | H12: =G12-F12 -> 18.4
A13: chantilli | B13: bolsa | C13: 28 | D13: onzas | E13: 24 | F13: =E13/C13 -> 0.85714286 | G13: 0.85714286 | H13: =G13-F13 -> 0
A14: mermelada | B14: frasco | C14: 32 | D14: onzas | E14: 23 | F14: =E14/C14 -> 0.71875 | G14: 0.9375 | H14: =G14-F14 -> 0.21875
A15: Mermelada Piña | B15: Bolsa | C15: 2.2 | D15: lb | E15: 16 | F15: =E15/C15 -> 7.2727273
A16: Crema pastelera | B16: Bolsa | C16: 2.2 | D16: lb | E16: 12.5 | F16: =E16/C16 -> 5.6818182
A17: rellenos | B17: bolsa | C17: 2.2 | D17: lb | E17: 16 | F17: =E17/C17 -> 7.2727273 | G17: 10.454545 | H17: =G17-F17 -> 3.1818182
A18: Chispitas | B18: libras | C18: 1 | D18: lb | E18: 21 | F18: =E18/C18 -> 21 | G18: 21 | H18: =G18-F18 -> 0
A19: aceite | B19: botella | C19: 1 | D19: lb | E19: 4 | F19: =E19/C19 -> 4 | G19: 4 | H19: =G19-F19 -> 0
A20: Leche | B20: Litro | C20: 1 | D20: Lt | E20: 14 | F20: =E20/C20 -> 14 | G20: 14 | H20: =G20-F20 -> 0
A21: colorante | B21: onzas | C21: 1 | D21: Libra | E21: 48 | F21: =E21/C21 -> 48
A22: Sal | B22: saco | C22: 10 | D22: lb | E22: 15 | F22: =E22/C22 -> 1.5 | G22: 1 | H22: =G22-F22 -> -0.5
A23: Carne | B23: libras | C23: 1 | D23: lb | E23: =32+1+1+2 -> 36 | F23: =E23/C23 -> 36
A24: Manteca | B24: caja | C24: 27 | D24: lb | E24: 207 | F24: =E24/C24 -> 7.6666667 | G24: 7.7777778 | H24: =G24-F24 -> 0.11111111
A25: Agua | B25: palangana | C25: 1 | D25: libra | E25: 0.5 | F25: =E25/C25 -> 0.5 | G25: 0.03125 | H25: =G25-F25 -> -0.46875
A26: Jamon | B26: libras | C26: 1 | D26: lb | E26: 59.85 | F26: =E26/C26 -> 59.85
A27: Bicarbonato | B27: bolsa | C27: 1 | D27: bolsa | E27: 1 | F27: =E27/C27 -> 1 | G27: 1.03125 | H27: =G27-F27 -> 0.03125
A28: Margarina Industrial | B28: libras | C28: 5 | D28: lb | E28: 50 | F28: =E28/C28 -> 10 | G28: 7.1666667 | H28: =G28-F28 -> -2.8333333
A29: Margarina de Hojaldre | B29: libras | C29: 5 | D29: lb | E29: 50 | F29: =E29/C29 -> 10 | G29: 9.3333333 | H29: =G29-F29 -> -0.66666667
A30: Margarina | B30: onzas | C30: 4 | D30: onzas | E30: 2.5 | F30: =E30/C30 -> 0.625
A31: Chocolate | B31: libras | C31: 2 | D31: lb | E31: 22 | F31: =E31/C31 -> 11 | G31: 11 | H31: =G31-F31 -> 0
A32: Banano | B32: unidad | C32: 12 | D32: unidades | E32: 6 | F32: =E32/C32 -> 0.5 | G32: 0.5 | H32: =G32-F32 -> 0
A33: Huevos | B33: Carton | C33: 30 | D33: UNIDADES | E33: 45 | F33: =E33/C33 -> 1.5 | G33: 1 | H33: =G33-F33 -> -0.5
A34: Vainilla | B34: LITRO | C34: 600 | D34: TAPITAS | E34: 40 | F34: =E34/C34 -> 0.066666667 | G34: 0.058333333 | H34: =G34-F34 -> -0.0083333333
A35: CANELA | B35: BOLSA | C35: 16 | D35: ONZAS | E35: 40 | F35: =E35/C35 -> 2.5 | G35: 2.5 | H35: =G35-F35 -> 0
H36: =SUM(H6:H35) -> 16.425846
A37: Materiales de empaque
A38: Tipo | B38: Dimension (cm) | C38: Cantidad | D38: Valor Q. | E38: Costo Unitario
A39: Bolsa 2 Lb | B39: 16X20 | C39: 500 | D39: 9 | E39: =D39/C39 -> 0.018
A40: Bolsa 5 Lb | B40: 23X20 | C40: 500 | D40: 12 | E40: =D40/C40 -> 0.024
A41: Bolsa Gabachita | B41: Gabachita | C41: 300 | D41: 20 | E41: =D41/C41 -> 0.066666667
A42: Funda cubiletes | B42: #2 | C42: 10000 | D42: 260 | E42: =D42/C42 -> 0.026
...

Sheet Rosca de Color
B2: Roscas de color
B3: Materia Prima | C3: Formula % | D3: Libras | E3: Onzas | F3: Conversion (lb) | G3: Costo Q. por Lb o Unidad empeado (Lb X costo Unitario | H3: Costo *Lb | I3: Proporcion de la formula (conversion LB/Total de conversion de ingredientes | J3: Formula para una unidad de (1.01 Onza) | K3: Costo Q por unidad de pan
B4: Harina Dura | C4: 1 | D4: 5 | F4: =IFERROR(D4+E4/16,"") -> 5 | G4: =IFERROR(VLOOKUP(B4,'MP Pan'!$A$6:$F$35,6,FALSE),0) -> 2.85 | H4: =F4*G4 -> 14.25 | I4: =F4/$F$14 -> 0.48338369 | J4: =$D$20*I4 -> 1.2307692 | K4: =(G4/16)*J4 -> 0.21923077
B5: Levadura | C5: =IFERROR(($C$4*F5)/$D$4,"") -> 0.025 | E5: 2 | F5: =IFERROR(D5+E5/16,"") -> 0.125 | G5: =IFERROR(VLOOKUP(B5,'MP Pan'!$A$6:$F$35,6,FALSE),0) -> 11.5 | H5: =F5*G5 -> 1.4375 | I5: =F5/$F$14 -> 0.012084592 | J5: =$D$20*I5 -> 0.030769231 | K5: =(G5/16)*J5 -> 0.022115385
B6: Sal | C6: =IFERROR(($C$4*F6)/$D$4,"") -> 0.00625 | E6: 0.5 | F6: =IFERROR(D6+E6/16,"") -> 0.03125 | G6: =IFERROR(VLOOKUP(B6,'MP Pan'!$A$6:$F$35,6,FALSE),0) -> 1.5 | H6: =F6*G6 -> 0.046875 | I6: =F6/$F$14 -> 0.003021148 | J6: =$D$20*I6 -> 0.0076923077 | K6: =(G6/16)*J6 -> 0.00072115385
B7: Azucar | C7: =IFERROR(($C$4*F7)/$D$4,"") -> 0.425 | D7: 2 | E7: 2 | F7: =IFERROR(D7+E7/16,"") -> 2.125 | G7: =IFERROR(VLOOKUP(B7,'MP Pan'!$A$6:$F$35,6,FALSE),0) -> 4.5 | H7: =F7*G7 -> 9.5625 | I7: =F7/$F$14 -> 0.20543807 | J7: =$D$20*I7 -> 0.52307692 | K7: =(G7/16)*J7 -> 0.14711538
B8: Manteca | C8: =IFERROR(($C$4*F8)/$D$4,"") -> 0.1 | E8: 8 | F8: =IFERROR(D8+E8/16,"") -> 0.5 | G8: =IFERROR(VLOOKUP(B8,'MP Pan'!$A$6:$F$35,6,FALSE),0) -> 7.6666667 | H8: =F8*G8 -> 3.8333333 | I8: =F8/$F$14 -> 0.048338369 | J8: =$D$20*I8 -> 0.12307692 | K8: =(G8/16)*J8 -> 0.058974359
B9: Agua | C9: =IFERROR(($C$4*F9)/$D$4,"") -> 0.5 | D9: 2 | E9: 8 | F9: =IFERROR(D9+E9/16,"") -> 2.5 | G9: =IFERROR(VLOOKUP(B9,'MP Pan'!$A$6:$F$35,6,FALSE),0) -> 0.5 | H9: =F9*G9 -> 1.25 | I9: =F9/$F$14 -> 0.24169184 | J9: =$D$20*I9 -> 0.61538462 | K9: =(G9/16)*J9 -> 0.019230769
B10: colorante | C10: =IFERROR(($C$4*F10)/$D$4,"") -> 0.0125 | E10: 1 | F10: =IFERROR(D10+E10/16,"") -> 0.0625 | G10: =IFERROR(VLOOKUP(B10,'MP Pan'!$A$6:$F$35,6,FALSE),0) -> 48 | H10: =F10*G10 -> 3 | I10: =F10/$F$14 -> 0.0060422961 | J10: =$D$20*I10 -> 0.015384615 | K10: =(G10/16)*J10 -> 0.046153846
C11: =IFERROR(($C$4*F11)/$D$4,"") -> 0 | F11: =IFERROR(D11+E11/16,"") -> 0 | G11: =IFERROR(VLOOKUP(B11,'MP Pan'!$A$6:$F$35,6,FALSE),0) -> 0 | H11: =F11*G11 -> 0 | I11: =F11/$F$14 -> 0 | J11: =$D$20*I11 -> 0 | K11: =(G11/16)*J11 -> 0
C12: =IFERROR(($C$4*F12)/$D$4,"") -> 0 | F12: =IFERROR(D12+E12/16,"") -> 0 | G12: =IFERROR(VLOOKUP(B12,'MP Pan'!$A$6:$F$35,6,FALSE),0) -> 0 | H12: =F12*G12 -> 0 | I12: =F12/$F$14 -> 0 | J12: =$D$20*I12 -> 0 | K12: =(G12/16)*J12 -> 0
C13: =IFERROR(($C$4*F13)/$D$4,"") -> 0 | F13: =IFERROR(D13+E13/16," ") -> 0 | G13: =IFERROR(VLOOKUP(B13,'MP Pan'!$A$6:$F$35,6,FALSE),0) -> 0 | H13: =F13*G13 -> 0 | I13: =F13/$F$14 -> 0 | J13: =$D$20*I13 -> 0 | K13: =(G13/16)*J13 -> 0
B14: Total | D14: =SUM(D4:D13) -> 9 | E14: =SUM(E4:E13) -> 21.5 | F14: =SUM(F4:F13) -> 10.34375 | G14: =SUM(G4:G13) -> 76.516667 | H14: =SUM(H4:H13) -> 33.380208 | I14: =SUM(I4:I13) -> 1 | J14: =$D$20*I14 -> 2.5461538 | K14: =SUM(K4:K13) -> 0.51354167
C16: Con esta fórmiula puedo producir | D16: =13*5 -> 65 | E16: =_xlfn.CONCAT("Pan ",B2,) -> Pan Roscas de color | G16: Producción Mensual | H16: =D16*30 -> 1950
C17: PVP | D17: 1 | G17: Venta Mensual Q. | H17: =H16*D17 -> 1950
C19: Total de Onzas | D19: =F14*16 -> 165.5
C20: Onzas por pan | D20: =D19/D16 -> 2.5461538
C22: Costo Total Diario | E22: =H14*1.36 -> 45.397083
C23: Venta Total Diaria | E23: =D17*D16 -> 65
C24: Ganancia Diaria | E24: =E23-E22 -> 19.602917
C25: % de ganancia | E25: =E24/E22 -> 0.43181005
B28: Preparación:

Sheet Empanada Salpor
B2: Empanadas Flo y Marce
B3: Materia Prima | C3: Formula % | D3: Libras | E3: Onzas | F3: Conversion (lb) | G3: Costo Q. por Lb o Unidad empeado (Lb X costo Unitario | H3: Costo *Lb | I3: Proporcion de la formula (conversion LB/Total de conversion de ingredientes | J3: Formula para una unidad de (1.01 Onza) | K3: Costo Q por unidad de pan
B4: Harina suave | C4: 1 | D4: 1 | F4: =IFERROR(D4+E4/16,"") -> 1 | G4: =IFERROR(VLOOKUP(B4,'MP Pan'!$A$6:$F$35,6,FALSE),0) -> 2.85 | H4: =F4*G4 -> 2.85 | I4: =F4/$F$15 -> 0.15259895 | J4: =$D$21*I4 -> 0.8 | K4: =(G4/16)*J4 -> 0.1425
B5: salpor | C5: =IFERROR(($C$4*F5)/$D$4,"") -> 0.75 | E5: 12 | F5: =IFERROR(D5+E5/16,"") -> 0.75 | G5: =IFERROR(VLOOKUP(B5,'MP Pan'!$A$6:$F$35,6,FALSE),0) -> 13 | H5: =F5*G5 -> 9.75 | I5: =F5/$F$15 -> 0.11444921 | J5: =$D$21*I5 -> 0.6 | K5: =(G5/16)*J5 -> 0.4875
B6: azucar | C6: =IFERROR(($C$4*F6)/$D$4,"") -> 0.5 | E6: 8 | F6: =IFERROR(D6+E6/16,"") -> 0.5 | G6: =IFERROR(VLOOKUP(B6,'MP Pan'!$A$6:$F$35,6,FALSE),0) -> 4.5 | H6: =F6*G6 -> 2.25 | I6: =F6/$F$15 -> 0.076299475 | J6: =$D$21*I6 -> 0.4 | K6: =(G6/16)*J6 -> 0.1125
B7: margarina | C7: =IFERROR(($C$4*F7)/$D$4,"") -> 0.375 | E7: 6 | F7: =IFERROR(D7+E7/16,"") -> 0.375 | G7: =IFERROR(VLOOKUP(B7,'MP Pan'!$A$6:$F$35,6,FALSE),0) -> 0.625 | H7: =F7*G7 -> 0.234375 | I7: =F7/$F$15 -> 0.057224607 | J7: =$D$21*I7 -> 0.3 | K7: =(G7/16)*J7 -> 0.01171875
B8: huevos | C8: =IFERROR(($C$4*F8)/$D$4,"") -> 2 | D8: 2 | F8: =IFERROR(D8+E8/16,"") -> 2 | G8: =IFERROR(VLOOKUP(B8,'MP Pan'!$A$6:$F$35,6,FALSE),0) -> 1.5 | H8: =F8*G8 -> 3 | I8: =F8/$F$15 -> 0.3051979 | J8: =$D$21*I8 -> 1.6 | K8: =(G8/16)*J8 -> 0.15
B9: vainilla | E9: 1 | F9: =IFERROR(D9+E9/16,"") -> 0.0625 | G9: =IFERROR(VLOOKUP(B9,'MP Pan'!$A$6:$F$35,6,FALSE),0) -> 0.066666667 | H9: =F9*G9 -> 0.0041666667 | I9: =F9/$F$15 -> 0.0095374344 | J9: =$D$21*I9 -> 0.05 | K9: =(G9/16)*J9 -> 0.00020833333
B10: royal | C10: 0 | E10: 1 | F10: =IFERROR(D10+E10/16,"") -> 0.0625 | G10: =IFERROR(VLOOKUP(B10,'MP Pan'!$A$6:$F$35,6,FALSE),0) -> 4.6 | H10: =F10*G10 -> 0.2875 | I10: =F10/$F$15 -> 0.0095374344 | J10: =$D$21*I10 -> 0.05 | K10: =(G10/16)*J10 -> 0.014375
B11: Sal | C11: =IFERROR(($C$4*F11)/$D$4,"") -> 0.03125 | E11: 0.5 | F11: =IFERROR(D11+E11/16,"") -> 0.03125 | G11: =IFERROR(VLOOKUP(B11,'MP Pan'!$A$6:$F$35,6,FALSE),0) -> 1.5 | H11: =F11*G11 -> 0.046875 | I11: =F11/$F$15 -> 0.0047687172 | J11: =$D$21*I11 -> 0.025 | K11: =(G11/16)*J11 -> 0.00234375
B12: colorante | C12: =IFERROR(($C$4*F12)/$D$4,"") -> 0.334375 | E12: 5.35 | F12: =IFERROR(D12+E12/16,"") -> 0.334375 | G12: =IFERROR(VLOOKUP(B12,'MP Pan'!$A$6:$F$35,6,FALSE),0) -> 48 | H12: =F12*G12 -> 16.05 | I12: =F12/$F$15 -> 0.051025274 | J12: =$D$21*I12 -> 0.2675 | K12: =(G12/16)*J12 -> 0.8025
B13: agua | C13: =IFERROR(($C$4*F13)/$D$4,"") -> 0.5625 | E13: 9 | F13: =IFERROR(D13+E13/16,"") -> 0.5625 | G13: =IFERROR(VLOOKUP(B13,'MP Pan'!$A$6:$F$35,6,FALSE),0) -> 0.5 | H13: =F13*G13 -> 0.28125 | I13: =F13/$F$15 -> 0.08583691 | J13: =$D$21*I13 -> 0.45 | K13: =(G13/16)*J13 -> 0.0140625
B14: rellenos | C14: =IFERROR(($C$4*F14)/$D$4,"") -> 0.875 | E14: 14 | F14: =IFERROR(D14+E14/16," ") -> 0.875 | G14: =IFERROR(VLOOKUP(B14,'MP Pan'!$A$6:$F$35,6,FALSE),0) -> 7.2727273 | H14: =F14*G14 -> 6.3636364 | I14: =F14/$F$15 -> 0.13352408 | J14: =$D$21*I14 -> 0.7 | K14: =(G14/16)*J14 -> 0.31818182
B15: Total | D15: =SUM(D4:D14) -> 3 | E15: =SUM(E4:E14) -> 56.85 | F15: =SUM(F4:F14) -> 6.553125 | G15: =SUM(G4:G14) -> 84.414394 | H15: =SUM(H4:H14) -> 41.117803 | I15: =SUM(I4:I14) -> 1 | J15: =$D$21*I15 -> 5.2425 | K15: =SUM(K4:K14) -> 2.0558902
K16: =K15*1.36 -> 2.7960106
C17: Con esta fórmiula puedo producir | D17: 20 | E17: =_xlfn.CONCAT("Pan ",B2,) -> Pan Empanadas Flo y Marce | G17: Producción Mensual | H17: 20
C18: PVP | D18: 5 | G18: Venta Mensual Q. | H18: =H17*D18 -> 100
C20: Total de Onzas | D20: =F15*16 -> 104.85
C21: Onzas por pan | D21: =D20/D17 -> 5.2425
C23: Costo Total Diario | E23: =H15*1.36 -> 55.920212
C24: Venta Total Diaria | E24: =D18*D17 -> 100
C25: Ganancia Diaria | E25: =E24-E23 -> 44.079788
C26: % de ganancia | E26: =E25/E23 -> 0.78826217

Sheet Empanadas Flo
B2: Empanadas Flo y Marce
B3: Materia Prima | C3: Formula % | D3: Libras | E3: Onzas | F3: Conversion (lb) | G3: Costo Q. por Lb o Unidad empeado (Lb X costo Unitario | H3: Costo *Lb | I3: Proporcion de la formula (conversion LB/Total de conversion de ingredientes | J3: Formula para una unidad de (1.01 Onza) | K3: Costo Q por unidad de pan
B4: Harina Suave Flo | C4: 1 | D4: 1 | F4: =IFERROR(D4+E4/16,"") -> 1 | G4: =IFERROR(VLOOKUP(B4,'MP Pan'!$A$6:$F$35,6,FALSE),0) -> 7.5 | H4: =F4*G4 -> 7.5 | I4: =F4/$F$14 -> 0.2962963 | J4: =$D$20*I4 -> 0.8 | K4: =(G4/16)*J4 -> 0.375
B5: Mermelada Piña | C5: =IFERROR(($C$4*F5)/$D$4,"") -> 0.3125 | E5: 5 | F5: =IFERROR(D5+E5/16,"") -> 0.3125 | G5: =IFERROR(VLOOKUP(B5,'MP Pan'!$A$6:$F$35,6,FALSE),0) -> 7.2727273 | H5: =F5*G5 -> 2.2727273 | I5: =F5/$F$14 -> 0.092592593 | J5: =$D$20*I5 -> 0.25 | K5: =(G5/16)*J5 -> 0.11363636
B6: Crema Pastelera | C6: =IFERROR(($C$4*F6)/$D$4,"") -> 0.3125 | E6: 5 | F6: =IFERROR(D6+E6/16,"") -> 0.3125 | G6: =IFERROR(VLOOKUP(B6,'MP Pan'!$A$6:$F$35,6,FALSE),0) -> 5.6818182 | H6: =F6*G6 -> 1.7755682 | I6: =F6/$F$14 -> 0.092592593 | J6: =$D$20*I6 -> 0.25 | K6: =(G6/16)*J6 -> 0.088778409
B7: Margarina industrial | C7: =IFERROR(($C$4*F7)/$D$4,"") -> 0.5 | E7: 8 | F7: =IFERROR(D7+E7/16,"") -> 0.5 | G7: =IFERROR(VLOOKUP(B7,'MP Pan'!$A$6:$F$35,6,FALSE),0) -> 10 | H7: =F7*G7 -> 5 | I7: =F7/$F$14 -> 0.14814815 | J7: =$D$20*I7 -> 0.4 | K7: =(G7/16)*J7 -> 0.25
B8: Agua | C8: =IFERROR(($C$4*F8)/$D$4,"") -> 0.25 | E8: 4 | F8: =IFERROR(D8+E8/16,"") -> 0.25 | G8: =IFERROR(VLOOKUP(B8,'MP Pan'!$A$6:$F$35,6,FALSE),0) -> 0.5 | H8: =F8*G8 -> 0.125 | I8: =F8/$F$14 -> 0.074074074 | J8: =$D$20*I8 -> 0.2 | K8: =(G8/16)*J8 -> 0.00625
B9: huevos | C9: 0 | D9: 1 | F9: =IFERROR(D9+E9/16,"") -> 1 | G9: =IFERROR(VLOOKUP(B9,'MP Pan'!$A$6:$F$35,6,FALSE),0) -> 1.5 | H9: =F9*G9 -> 1.5 | I9: =F9/$F$14 -> 0.2962963 | J9: =$D$20*I9 -> 0.8 | K9: =(G9/16)*J9 -> 0.075
C10: =IFERROR(($C$4*F10)/$D$4,"") -> 0 | F10: =IFERROR(D10+E10/16,"") -> 0 | G10: =IFERROR(VLOOKUP(B10,'MP Pan'!$A$6:$F$35,6,FALSE),0) -> 0 | H10: =F10*G10 -> 0 | I10: =F10/$F$14 -> 0 | J10: =$D$20*I10 -> 0 | K10: =(G10/16)*J10 -> 0
C11: =IFERROR(($C$4*F11)/$D$4,"") -> 0 | F11: =IFERROR(D11+E11/16,"") -> 0 | G11: =IFERROR(VLOOKUP(B11,'MP Pan'!$A$6:$F$35,6,FALSE),0) -> 0 | H11: =F11*G11 -> 0 | I11: =F11/$F$14 -> 0 | J11: =$D$20*I11 -> 0 | K11: =(G11/16)*J11 -> 0
C12: =IFERROR(($C$4*F12)/$D$4,"") -> 0 | F12: =IFERROR(D12+E12/16,"") -> 0 | G12: =IFERROR(VLOOKUP(B12,'MP Pan'!$A$6:$F$35,6,FALSE),0) -> 0 | H12: =F12*G12 -> 0 | I12: =F12/$F$14 -> 0 | J12: =$D$20*I12 -> 0 | K12: =(G12/16)*J12 -> 0
C13: =IFERROR(($C$4*F13)/$D$4,"") -> 0 | F13: =IFERROR(D13+E13/16," ") -> 0 | G13: =IFERROR(VLOOKUP(B13,'MP Pan'!$A$6:$F$35,6,FALSE),0) -> 0 | H13: =F13*G13 -> 0 | I13: =F13/$F$14 -> 0 | J13: =$D$20*I13 -> 0 | K13: =(G13/16)*J13 -> 0
B14: Total | D14: =SUM(D4:D13) -> 2 | E14: =SUM(E4:E13) -> 22 | F14: =SUM(F4:F13) -> 3.375 | G14: =SUM(G4:G13) -> 32.454545 | H14: =SUM(H4:H13) -> 18.173295 | I14: =SUM(I4:I13) -> 1 | J14: =$D$20*I14 -> 2.7 | K14: =SUM(K4:K13) -> 0.90866477
C16: Con esta fórmiula puedo producir | D16: 20 | E16: =_xlfn.CONCAT("Pan ",B2,) -> Pan Empanadas Flo y Marce | G16: Producción Mensual | H16: 20
C17: PVP | D17: 3 | G17: Venta Mensual Q. | H17: =H16*D17 -> 60
C19: Total de Onzas | D19: =F14*16 -> 54
C20: Onzas por pan | D20: =D19/D16 -> 2.7
C22: Costo Total Diario | E22: =H14*1.36 -> 24.715682
C23: Venta Total Diaria | E23: =D17*D16 -> 60
C24: Ganancia Diaria | E24: =E23-E22 -> 35.284318
C25: % de ganancia | E25: =E24/E22 -> 1.4276085

Sheet SHUCOS
B2: SHUCOS
B3: Materia Prima | C3: Formula % | D3: Libras | E3: Onzas | F3: Conversion (lb) | G3: Costo Q. por Lb o Unidad empeado (Lb X costo Unitario | H3: Costo *Lb | I3: Proporcion de la formula (conversion LB/Total de conversion de ingredientes | J3: =_xlfn.CONCAT("Formula para una unidad de (",J14,"Onza)") -> Formula para una unidad de (2.58333333333333Onza) | K3: Costo Q por unidad de pan
B4: Harina Dura | C4: 1 | D4: 5 | F4: =IFERROR(D4+E4/16,"") -> 5 | G4: =IFERROR(VLOOKUP(B4,'MP Pan'!$A$6:$F$35,6,FALSE),0) -> 2.85 | H4: =F4*G4 -> 14.25 | I4: =F4/$F$14 -> 0.51612903 | J4: =$D$20*I4 -> 1.3333333 | K4: =(G4/16)*J4 -> 0.2375
B5: Levadura | C5: =IFERROR(($C$4*F5)/$D$4,"") -> 0.0375 | E5: 3 | F5: =IFERROR(D5+E5/16,"") -> 0.1875 | G5: =IFERROR(VLOOKUP(B5,'MP Pan'!$A$6:$F$35,6,FALSE),0) -> 11.5 | H5: =F5*G5 -> 2.15625 | I5: =F5/$F$14 -> 0.019354839 | J5: =$D$20*I5 -> 0.05 | K5: =(G5/16)*J5 -> 0.0359375
B6: Sal | C6: =IFERROR(($C$4*F6)/$D$4,"") -> 0.0125 | E6: 1 | F6: =IFERROR(D6+E6/16,"") -> 0.0625 | G6: =IFERROR(VLOOKUP(B6,'MP Pan'!$A$6:$F$35,6,FALSE),0) -> 1.5 | H6: =F6*G6 -> 0.09375 | I6: =F6/$F$14 -> 0.0064516129 | J6: =$D$20*I6 -> 0.016666667 | K6: =(G6/16)*J6 -> 0.0015625
B7: Azucar | C7: =IFERROR(($C$4*F7)/$D$4,"") -> 0.0375 | E7: 3 | F7: =IFERROR(D7+E7/16,"") -> 0.1875 | G7: =IFERROR(VLOOKUP(B7,'MP Pan'!$A$6:$F$35,6,FALSE),0) -> 4.5 | H7: =F7*G7 -> 0.84375 | I7: =F7/$F$14 -> 0.019354839 | J7: =$D$20*I7 -> 0.05 | K7: =(G7/16)*J7 -> 0.0140625
B8: Manteca | C8: =IFERROR(($C$4*F8)/$D$4,"") -> 0.05 | E8: 4 | F8: =IFERROR(D8+E8/16,"") -> 0.25 | G8: =IFERROR(VLOOKUP(B8,'MP Pan'!$A$6:$F$35,6,FALSE),0) -> 7.6666667 | H8: =F8*G8 -> 1.9166667 | I8: =F8/$F$14 -> 0.025806452 | J8: =$D$20*I8 -> 0.066666667 | K8: =(G8/16)*J8 -> 0.031944444
B9: Agua | C9: =IFERROR(($C$4*F9)/$D$4,"") -> 0.8 | D9: 4 | F9: =IFERROR(D9+E9/16,"") -> 4 | G9: =IFERROR(VLOOKUP(B9,'MP Pan'!$A$6:$F$35,6,FALSE),0) -> 0.5 | H9: =F9*G9 -> 2 | I9: =F9/$F$14 -> 0.41290323 | J9: =$D$20*I9 -> 1.0666667 | K9: =(G9/16)*J9 -> 0.033333333
C10: =IFERROR(($C$4*F10)/$D$4,"") -> 0 | F10: =IFERROR(D10+E10/16,"") -> 0 | G10: =IFERROR(VLOOKUP(B10,'MP Pan'!$A$6:$F$35,6,FALSE),0) -> 0 | H10: =F10*G10 -> 0 | I10: =F10/$F$14 -> 0 | J10: =$D$20*I10 -> 0 | K10: =(G10/16)*J10 -> 0
C11: =IFERROR(($C$4*F11)/$D$4,"") -> 0 | F11: =IFERROR(D11+E11/16,"") -> 0 | G11: =IFERROR(VLOOKUP(B11,'MP Pan'!$A$6:$F$35,6,FALSE),0) -> 0 | H11: =F11*G11 -> 0 | I11: =F11/$F$14 -> 0 | J11: =$D$20*I11 -> 0 | K11: =(G11/16)*J11 -> 0
C12: =IFERROR(($C$4*F12)/$D$4,"") -> 0 | F12: =IFERROR(D12+E12/16,"") -> 0 | G12: =IFERROR(VLOOKUP(B12,'MP Pan'!$A$6:$F$35,6,FALSE),0) -> 0 | H12: =F12*G12 -> 0 | I12: =F12/$F$14 -> 0 | J12: =$D$20*I12 -> 0 | K12: =(G12/16)*J12 -> 0
C13: =IFERROR(($C$4*F13)/$D$4,"") -> 0 | F13: =IFERROR(D13+E13/16," ") -> 0 | G13: =IFERROR(VLOOKUP(B13,'MP Pan'!$A$6:$F$35,6,FALSE),0) -> 0 | H13: =F13*G13 -> 0 | I13: =F13/$F$14 -> 0 | J13: =$D$20*I13 -> 0 | K13: =(G13/16)*J13 -> 0
B14: Total | D14: =SUM(D4:D13) -> 9 | E14: =SUM(E4:E13) -> 11 | F14: =SUM(F4:F13) -> 9.6875 | G14: =SUM(G4:G13) -> 28.516667 | H14: =SUM(H4:H13) -> 21.260417 | I14: =SUM(I4:I13) -> 1 | J14: =$D$20*I14 -> 2.5833333 | K14: =SUM(K4:K13) -> 0.35434028
C16: Con esta fórmiula puedo producir | D16: 60 | E16: =_xlfn.CONCAT("Pan ",B2,) -> Pan SHUCOS | G16: Producción Mensual | H16: =D16*30 -> 1800
C17: PVP | D17: 1.25 | G17: Venta Mensual Q. | H17: =H16*D17 -> 2250
C19: Total de Onzas | D19: =F14*16 -> 155
C20: Onzas por pan | D20: =D19/D16 -> 2.5833333
C22: Costo Total Diario | E22: =H14*1.36 -> 28.914167
C23: Venta Total Diaria | E23: =D17*D16 -> 75
C24: Ganancia Diaria | E24: =E23-E22 -> 46.085833
C25: % de ganancia | E25: =E24/E22 -> 1.5938842

Sheet Formulación
A2: Producción de Manteca
A3: Materia Prima | B3: Formula % | C3: Conversion (lb) | D3: Costo Q. por Lb o Unidad empeado (Lb X costo Unitario | E3: Proporcion de la formula (conversion LB/Total de conversion de ingredientes | F3: Formula para una unidad de (1.01 Onza) | G3: Costo Q por unidad de pan
A4: Harina Suave | B4: 1 | C4: 3 | D4: =VLOOKUP(A4,'MP Pan'!$A$6:$F$35,6,FALSE) -> 2.85 | E4: =C4/$C$11 -> 0.34407616 | F4: =$E$14*E4 -> 0.24242424 | G4: =(D4/16)*F4 -> 0.043181818
A5: Azucar | B5: =($B$4*C5)/$C$4 -> 0.5 | C5: 1.5 | D5: =VLOOKUP(A5,'MP Pan'!$A$6:$F$35,6,FALSE) -> 4.5 | E5: =C5/$C$11 -> 0.17203808 | F5: =$E$14*E5 -> 0.12121212 | G5: =(D5/16)*F5 -> 0.034090909
A6: sal | B6: =($B$4*C6)/$C$4 -> 0.010333333 | C6: 0.031 | D6: =VLOOKUP(A6,'MP Pan'!$A$6:$F$35,6,FALSE) -> 1.5 | E6: =C6/$C$11 -> 0.0035554536 | F6: =$E$14*E6 -> 0.0025050505 | G6: =(D6/16)*F6 -> 0.00023484848
A7: Royal | B7: =($B$4*C7)/$C$4 -> 0.5 | C7: 1.5 | D7: =VLOOKUP(A7,'MP Pan'!$A$6:$F$35,6,FALSE) -> 4.6 | E7: =C7/$C$11 -> 0.17203808 | F7: =$E$14*E7 -> 0.12121212 | G7: =(D7/16)*F7 -> 0.034848485
A8: Manteca | B8: =($B$4*C8)/$C$4 -> 0.25 | C8: 0.75 | D8: =VLOOKUP(A8,'MP Pan'!$A$6:$F$35,6,FALSE) -> 7.6666667 | E8: =C8/$C$11 -> 0.086019039 | F8: =$E$14*E8 -> 0.060606061 | G8: =(D8/16)*F8 -> 0.029040404
A9: agua | B9: =($B$4*C9)/$C$4 -> 0.646 | C9: 1.938 | D9: =VLOOKUP(A9,'MP Pan'!$A$6:$F$35,6,FALSE) -> 0.5 | E9: =C9/$C$11 -> 0.2222732 | F9: =$E$14*E9 -> 0.15660606 | G9: =(D9/16)*F9 -> 0.0048939394
B10: =($B$4*C10)/$C$4 -> 0 | D10: =IFERROR(VLOOKUP(A10,'MP Pan'!$A$6:$F$35,6,FALSE),0) -> 0 | E10: =C10/$C$11 -> 0 | F10: =$E$14*E10 -> 0 | G10: =(D10/16)*F10 -> 0
A11: Total | C11: =SUM(C4:C10) -> 8.719 | D11: =SUM(D4:D10) -> 21.616667 | E11: =SUM(E4:E10) -> 1 | F11: =SUM(F4:F10) -> 0.70456566 | G11: =SUM(G4:G10) -> 0.1462904
B13: Con esta fórmiula puedo producir | C13: 198 | D13: Panes Dulces Diarios | E13: =C11*16 -> 139.504 | F13: Producción Mensual | G13: =C13*30 -> 5940
B14: PVP | C14: 0.33 | D14: =C14*C13 -> 65.34 | E14: =E13/C13 -> 0.70456566 | F14: Venta Mensual Q. | G14: =G13*C14 -> 1960.2
A16: Tostado
A17: Materia Prima | B17: Formula % | C17: Libras | D17: Onzas | E17: Conversion (lb) | F17: Costo Q. por Lb o Unidad empeado (Lb X costo Unitario | G17: Proporcion de la formula (conversion LB/Total de conversion de ingredientes | H17: Formula para una unidad de (1.01 Onza) | I17: Costo Q por unidad de pan
A18: Harina Suave | B18: 1 | C18: 3 | E18: =IFERROR(C18+D18/16,"") -> 3 | F18: =IFERROR(VLOOKUP(A18,'MP Pan'!$A$6:$F$35,6,FALSE),0) -> 2.85 | G18: =E18/$E$25 -> 0.34408602 | H18: =$E$28*G18 -> 0.24242424 | I18: =(F18/16)*H18 -> 0.043181818
A19: Azucar | B19: =($B$4*E19)/$C$4 -> 0.5 | C19: 1 | D19: 8 | E19: =IFERROR(C19+D19/16,"") -> 1.5 | F19: =IFERROR(VLOOKUP(A19,'MP Pan'!$A$6:$F$35,6,FALSE),0) -> 4.5 | G19: =E19/$E$25 -> 0.17204301 | H19: =$E$28*G19 -> 0.12121212 | I19: =(F19/16)*H19 -> 0.034090909
A20: sal | B20: =($B$4*E20)/$C$4 -> 0.010416667 | D20: 0.5 | E20: =IFERROR(C20+D20/16,"") -> 0.03125 | F20: =IFERROR(VLOOKUP(A20,'MP Pan'!$A$6:$F$35,6,FALSE),0) -> 1.5 | G20: =E20/$E$25 -> 0.0035842294 | H20: =$E$28*G20 -> 0.0025252525 | I20: =(F20/16)*H20 -> 0.00023674242
A21: Royal | B21: =($B$4*E21)/$C$4 -> 0.5 | C21: 1 | D21: 8 | E21: =IFERROR(C21+D21/16,"") -> 1.5 | F21: =IFERROR(VLOOKUP(A21,'MP Pan'!$A$6:$F$35,6,FALSE),0) -> 4.6 | G21: =E21/$E$25 -> 0.17204301 | H21: =$E$28*G21 -> 0.12121212 | I21: =(F21/16)*H21 -> 0.034848485
A22: Manteca | B22: =($B$4*E22)/$C$4 -> 0.25 | D22: 12 | E22: =IFERROR(C22+D22/16,"") -> 0.75 | F22: =IFERROR(VLOOKUP(A22,'MP Pan'!$A$6:$F$35,6,FALSE),0) -> 7.6666667 | G22: =E22/$E$25 -> 0.086021505 | H22: =$E$28*G22 -> 0.060606061 | I22: =(F22/16)*H22 -> 0.029040404
A23: Agua | B23: =($B$4*E23)/$C$4 -> 0.64583333 | C23: 1 | D23: 15 | E23: =IFERROR(C23+D23/16,"") -> 1.9375 | F23: =IFERROR(VLOOKUP(A23,'MP Pan'!$A$6:$F$35,6,FALSE),0) -> 0.5 | G23: =E23/$E$25 -> 0.22222222 | H23: =$E$28*G23 -> 0.15656566 | I23: =(F23/16)*H23 -> 0.0048926768
B24: =($B$4*E24)/$C$4 -> 0 | E24: =IFERROR(C24+D24/16," ") -> 0 | F24: =IFERROR(VLOOKUP(A24,'MP Pan'!$A$6:$F$35,6,FALSE),0) -> 0 | G24: =E24/$E$25 -> 0 | H24: =$E$28*G24 -> 0 | I24: =(F24/16)*H24 -> 0
A25: Total | C25: =SUM(C18:C24) -> 6 | D25: =SUM(D18:D24) -> 43.5 | E25: =SUM(E18:E24) -> 8.71875 | F25: =SUM(F18:F24) -> 21.616667 | G25: =SUM(G18:G24) -> 1 | H25: =$E$28*G25 -> 0.70454545 | I25: =SUM(I18:I24) -> 0.14629104
B27: Con esta fórmiula puedo producir | C27: 198 | D27: Panes Dulces Diarios | E27: =E25*16 -> 139.5 | F27: Producción Mensual | G27: =C27*30 -> 5940 | H27: =G27*I25 -> 868.96875
B28: PVP | C28: 0.33 | D28: =C28*C27 -> 65.34 | E28: =E27/C27 -> 0.70454545 | F28: Venta Mensual Q. | G28: =G27*C28 -> 1960.2 | H28: =G28-H27 -> 1091.2312
A30: Frances
A31: Materia Prima | B31: Formula % | C31: Libras | D31: Onzas | E31: Conversion (lb) | F31: Costo Q. por Lb o Unidad empeado (Lb X costo Unitario | G31: Proporcion de la formula (conversion LB/Total de conversion de ingredientes | H31: =_xlfn.CONCAT("Formula para una unidad de (",E42,"Onza)") -> Formula para una unidad de (0.823899371069182Onza) | I31: Costo Q por unidad de pan
A32: Harina Dura | B32: 1 | C32: 10 | E32: =IFERROR(C32+D32/16,"") -> 10 | F32: =IFERROR(VLOOKUP(A32,'MP Pan'!$A$6:$F$35,6,FALSE),0) -> 2.85 | G32: =E32/$E$39 -> 0.61068702 | H32: =$E$42*G32 -> 0.50314465 | I32: =(F32/16)*H32 -> 0.089622642
A33: Levadura | B33: =($B$4*E33)/$C$4 -> 0.083333333 | D33: 4 | E33: =IFERROR(C33+D33/16,"") -> 0.25 | F33: =IFERROR(VLOOKUP(A33,'MP Pan'!$A$6:$F$35,6,FALSE),0) -> 11.5 | G33: =E33/$E$39 -> 0.015267176 | H33: =$E$42*G33 -> 0.012578616 | I33: =(F33/16)*H33 -> 0.0090408805
A34: Sal | B34: =($B$4*E34)/$C$4 -> 0.041666667 | D34: 2 | E34: =IFERROR(C34+D34/16,"") -> 0.125 | F34: =IFERROR(VLOOKUP(A34,'MP Pan'!$A$6:$F$35,6,FALSE),0) -> 1.5 | G34: =E34/$E$39 -> 0.0076335878 | H34: =$E$42*G34 -> 0.0062893082 | I34: =(F34/16)*H34 -> 0.00058962264 | K34: 1 | L34: 3
A35: Azucar | B35: =($B$4*E35)/$C$4 -> 0.083333333 | D35: 4 | E35: =IFERROR(C35+D35/16,"") -> 0.25 | F35: =IFERROR(VLOOKUP(A35,'MP Pan'!$A$6:$F$35,6,FALSE),0) -> 4.5 | G35: =E35/$E$39 -> 0.015267176 | H35: =$E$42*G35 -> 0.012578616 | I35: =(F35/16)*H35 -> 0.0035377358 | K35: 0.75 | L35: =K35*$L$34 -> 2.25
A36: Manteca | B36: =($B$4*E36)/$C$4 -> 0.16666667 | D36: 8 | E36: =IFERROR(C36+D36/16,"") -> 0.5 | F36: =IFERROR(VLOOKUP(A36,'MP Pan'!$A$6:$F$35,6,FALSE),0) -> 7.6666667 | G36: =E36/$E$39 -> 0.030534351 | H36: =$E$42*G36 -> 0.025157233 | I36: =(F36/16)*H36 -> 0.012054507 | K36: 0.5 | L36: =K36*$L$34 -> 1.5
A37: Agua | B37: =($B$4*E37)/$C$4 -> 1.75 | C37: 5 | D37: 4 | E37: =IFERROR(C37+D37/16,"") -> 5.25 | F37: =IFERROR(VLOOKUP(A37,'MP Pan'!$A$6:$F$35,6,FALSE),0) -> 0.5 | G37: =E37/$E$39 -> 0.32061069 | H37: =$E$42*G37 -> 0.26415094 | I37: =(F37/16)*H37 -> 0.008254717 | K37: 0.25 | L37: =K37*$L$34 -> 0.75
B38: =($B$4*E38)/$C$4 -> 0 | E38: =IFERROR(C38+D38/16," ") -> 0 | F38: =IFERROR(VLOOKUP(A38,'MP Pan'!$A$6:$F$35,6,FALSE),0) -> 0 | G38: =E38/$E$39 -> 0 | H38: =$E$42*G38 -> 0 | I38: =(F38/16)*H38 -> 0
A39: Total | C39: =SUM(C32:C38) -> 15 | D39: =SUM(D33:D38) -> 22 | E39: =SUM(E32:E38) -> 16.375 | F39: =SUM(F32:F38) -> 28.516667 | G39: =SUM(G32:G38) -> 1 | H39: =$E$42*G39 -> 0.82389937 | I39: =SUM(I32:I38) -> 0.1231001
B41: Con esta fórmiula puedo producir | C41: 318 | D41: Pan Frances | E41: =E39*16 -> 262 | F41: Producción Mensual | G41: =C41*30 -> 9540
B42: PVP | C42: =2.25/8 -> 0.28125 | E42: =E41/C41 -> 0.82389937 | F42: Venta Mensual Q. | G42: =G41*C42 -> 2683.125
A44: Manteca
A45: Materia Prima | B45: Formula % | C45: Libras | D45: Onzas | E45: Conversion (lb) | F45: Costo Q. por Lb o Unidad empeado (Lb X costo Unitario | G45: Proporcion de la formula (conversion LB/Total de conversion de ingredientes | H45: Formula para una unidad de (1.01 Onza) | I45: Costo Q por unidad de pan
A46: Harina Suave | B46: 1 | C46: 5 | E46: =IFERROR(C46+D46/16,"") -> 5 | F46: =IFERROR(VLOOKUP(A46,'MP Pan'!$A$6:$F$35,6,FALSE),0) -> 2.85 | G46: =E46/$C$11 -> 0.57346026 | H46: =$E$56*G46 -> 0.45500306 | I46: =(F46/16)*H46 -> 0.081047421
A47: Azucar | B47: =($B$4*E47)/$C$4 -> 0.5 | C47: 1 | D47: 8 | E47: =IFERROR(C47+D47/16,"") -> 1.5 | F47: =IFERROR(VLOOKUP(A47,'MP Pan'!$A$6:$F$35,6,FALSE),0) -> 4.5 | G47: =E47/$C$11 -> 0.17203808 | H47: =$E$56*G47 -> 0.13650092 | I47: =(F47/16)*H47 -> 0.038390884
...

Sheet Tostado
B2: Tostado
B3: Materia Prima | C3: Formula % | D3: Libras | E3: Onzas | F3: Conversion (lb) | G3: Costo Q. por Lb o Unidad empeado (Lb X costo Unitario | H3: Costo *Lb | I3: Proporcion de la formula (conversion LB/Total de conversion de ingredientes | J3: Formula para una unidad de (1.01 Onza) | K3: Costo Q por unidad de pan
B4: Harina Suave | C4: 1 | D4: 3 | F4: =IFERROR(D4+E4/16,"") -> 3 | G4: =IFERROR(VLOOKUP(B4,'MP Pan'!$A$6:$F$35,6,FALSE),0) -> 2.85 | H4: =F4*G4 -> 8.55 | I4: =F4/$F$14 -> 0.38866397 | J4: =$D$20*I4 -> 0.24242424 | K4: =(G4/16)*J4 -> 0.043181818
B5: Azucar | C5: =($C$4*F5)/$D$4 -> 0.5 | D5: 1 | E5: 8 | F5: =IFERROR(D5+E5/16,"") -> 1.5 | G5: =IFERROR(VLOOKUP(B5,'MP Pan'!$A$6:$F$35,6,FALSE),0) -> 4.5 | H5: =F5*G5 -> 6.75 | I5: =F5/$F$14 -> 0.19433198 | J5: =$D$20*I5 -> 0.12121212 | K5: =(G5/16)*J5 -> 0.034090909
B6: sal | C6: =($C$4*F6)/$D$4 -> 0.010416667 | E6: 0.5 | F6: =IFERROR(D6+E6/16,"") -> 0.03125 | G6: =IFERROR(VLOOKUP(B6,'MP Pan'!$A$6:$F$35,6,FALSE),0) -> 1.5 | H6: =F6*G6 -> 0.046875 | I6: =F6/$F$14 -> 0.004048583 | J6: =$D$20*I6 -> 0.0025252525 | K6: =(G6/16)*J6 -> 0.00023674242
B7: Royal | C7: =($C$4*F7)/$D$4 -> 0.5 | D7: 1 | E7: 8 | F7: =IFERROR(D7+E7/16,"") -> 1.5 | G7: =IFERROR(VLOOKUP(B7,'MP Pan'!$A$6:$F$35,6,FALSE),0) -> 4.6 | H7: =F7*G7 -> 6.9 | I7: =F7/$F$14 -> 0.19433198 | J7: =$D$20*I7 -> 0.12121212 | K7: =(G7/16)*J7 -> 0.034848485
B8: Manteca | C8: =($C$4*F8)/$D$4 -> 0.25 | E8: 12 | F8: =IFERROR(D8+E8/16,"") -> 0.75 | G8: =IFERROR(VLOOKUP(B8,'MP Pan'!$A$6:$F$35,6,FALSE),0) -> 7.6666667 | H8: =F8*G8 -> 5.75 | I8: =F8/$F$14 -> 0.097165992 | J8: =$D$20*I8 -> 0.060606061 | K8: =(G8/16)*J8 -> 0.029040404
B9: Agua | C9: =($C$4*F9)/$D$4 -> 0.3125 | E9: 15 | F9: =IFERROR(D9+E9/16,"") -> 0.9375 | G9: =IFERROR(VLOOKUP(B9,'MP Pan'!$A$6:$F$35,6,FALSE),0) -> 0.5 | H9: =F9*G9 -> 0.46875 | I9: =F9/$F$14 -> 0.12145749 | J9: =$D$20*I9 -> 0.075757576 | K9: =(G9/16)*J9 -> 0.0023674242
C10: =($C$4*F10)/$D$4 -> 0 | F10: =IFERROR(D10+E10/16," ") -> 0 | G10: =IFERROR(VLOOKUP(B10,'MP Pan'!$A$6:$F$35,6,FALSE),0) -> 0 | H10: =F10*G10 -> 0 | I10: =F10/$F$14 -> 0 | J10: =$D$20*I10 -> 0 | K10: =(G10/16)*J10 -> 0
C11: =($C$4*F11)/$D$4 -> 0 | F11: =IFERROR(D11+E11/16," ") -> 0 | G11: =IFERROR(VLOOKUP(B11,'MP Pan'!$A$6:$F$35,6,FALSE),0) -> 0 | H11: =F11*G11 -> 0 | I11: =F11/$F$14 -> 0 | J11: =$D$20*I11 -> 0 | K11: =(G11/16)*J11 -> 0
C12: =($C$4*F12)/$D$4 -> 0 | F12: =IFERROR(D12+E12/16," ") -> 0 | G12: =IFERROR(VLOOKUP(B12,'MP Pan'!$A$6:$F$35,6,FALSE),0) -> 0 | H12: =F12*G12 -> 0 | I12: =F12/$F$14 -> 0 | J12: =$D$20*I12 -> 0 | K12: =(G12/16)*J12 -> 0
C13: =($C$4*F13)/$D$4 -> 0 | F13: =IFERROR(D13+E13/16," ") -> 0 | G13: =IFERROR(VLOOKUP(B13,'MP Pan'!$A$6:$F$35,6,FALSE),0) -> 0 | H13: =F13*G13 -> 0 | I13: =F13/$F$14 -> 0 | J13: =$D$20*I13 -> 0 | K13: =(G13/16)*J13 -> 0
B14: Total | D14: =SUM(D4:D13) -> 5 | E14: =SUM(E4:E13) -> 43.5 | F14: =SUM(F4:F13) -> 7.71875 | G14: =SUM(G4:G13) -> 21.616667 | H14: =SUM(H4:H13) -> 28.465625 | I14: =SUM(I4:I13) -> 1 | J14: =$D$20*I14 -> 0.62373737 | K14: =SUM(K4:K13) -> 0.14376578
C16: Con esta fórmiula puedo producir | D16: 198 | E16: =_xlfn.CONCAT("Pan ",B2,) -> Pan Tostado | G16: Producción Mensual | H16: =D16*30 -> 5940
C17: PVP | D17: 0.33 | G17: Venta Mensual Q. | H17: =H16*D17 -> 1960.2
C19: Total de Onzas | D19: =F14*16 -> 123.5
C20: Onzas por pan | D20: =D19/D16 -> 0.62373737
C22: Costo Total Diario | E22: =H14 -> 28.465625
C23: Venta Total Diaria | E23: =D17*D16 -> 65.34
C24: Ganancia Diaria | E24: =E23-E22 -> 36.874375
C25: % de ganancia | E25: =E24/E22 -> 1.2954002

Sheet Panitos de manteca
B2: Manteca 5 libras
B3: Materia Prima | C3: Formula % | D3: Libras | E3: Onzas | F3: Conversion (lb) | G3: Costo Q. por Lb o Unidad empeado (Lb X costo Unitario | H3: Costo *Lb | I3: Proporcion de la formula (conversion LB/Total de conversion de ingredientes | J3: Formula para una unidad de (1.01 Onza) | K3: Costo Q por unidad de pan
B4: Harina Suave | C4: 1 | D4: 5 | E4: 8 | F4: =IFERROR(D4+E4/16,"") -> 5.5 | G4: =IFERROR(VLOOKUP(B4,'MP Pan'!$A$6:$F$35,6,FALSE),0) -> 2.85 | H4: =F4*G4 -> 15.675 | I4: =F4/$F$14 -> 0.44221106 | J4: =$D$20*I4 -> 0.061111111 | K4: =(G4/16)*J4 -> 0.010885417
B5: Azucar | C5: =IFERROR(($C$4*F5)/$D$4,"") -> 0.35 | D5: 1 | E5: 12 | F5: =IFERROR(D5+E5/16,"") -> 1.75 | G5: =IFERROR(VLOOKUP(B5,'MP Pan'!$A$6:$F$35,6,FALSE),0) -> 4.5 | H5: =F5*G5 -> 7.875 | I5: =F5/$F$14 -> 0.14070352 | J5: =$D$20*I5 -> 0.019444444 | K5: =(G5/16)*J5 -> 0.00546875
B6: Levadura | C6: =IFERROR(($C$4*F6)/$D$4,"") -> 0.0125 | E6: 1 | F6: =IFERROR(D6+E6/16,"") -> 0.0625 | G6: =IFERROR(VLOOKUP(B6,'MP Pan'!$A$6:$F$35,6,FALSE),0) -> 11.5 | H6: =F6*G6 -> 0.71875 | I6: =F6/$F$14 -> 0.0050251256 | J6: =$D$20*I6 -> 0.00069444444 | K6: =(G6/16)*J6 -> 0.00049913194
B7: Royal | C7: =IFERROR(($C$4*F7)/$D$4,"") -> 0.0125 | E7: 1 | F7: =IFERROR(D7+E7/16,"") -> 0.0625 | G7: =IFERROR(VLOOKUP(B7,'MP Pan'!$A$6:$F$35,6,FALSE),0) -> 4.6 | H7: =F7*G7 -> 0.2875 | I7: =F7/$F$14 -> 0.0050251256 | J7: =$D$20*I7 -> 0.00069444444 | K7: =(G7/16)*J7 -> 0.00019965278
B8: Sal | C8: =IFERROR(($C$4*F8)/$D$4,"") -> 0.0125 | E8: 1 | F8: =IFERROR(D8+E8/16,"") -> 0.0625 | G8: =IFERROR(VLOOKUP(B8,'MP Pan'!$A$6:$F$35,6,FALSE),0) -> 1.5 | H8: =F8*G8 -> 0.09375 | I8: =F8/$F$14 -> 0.0050251256 | J8: =$D$20*I8 -> 0.00069444444 | K8: =(G8/16)*J8 -> 6.5104167e-05
B9: Manteca | C9: =IFERROR(($C$4*F9)/$D$4,"") -> 0.15 | E9: 12 | F9: =IFERROR(D9+E9/16,"") -> 0.75 | G9: =IFERROR(VLOOKUP(B9,'MP Pan'!$A$6:$F$35,6,FALSE),0) -> 7.6666667 | H9: =F9*G9 -> 5.75 | I9: =F9/$F$14 -> 0.060301508 | J9: =$D$20*I9 -> 0.0083333333 | K9: =(G9/16)*J9 -> 0.0039930556
B10: Agua | C10: =IFERROR(($C$4*F10)/$D$4,"") -> 0.85 | D10: 4 | E10: 4 | F10: =IFERROR(D10+E10/16,"") -> 4.25 | G10: =IFERROR(VLOOKUP(B10,'MP Pan'!$A$6:$F$35,6,FALSE),0) -> 0.5 | H10: =F10*G10 -> 2.125 | I10: =F10/$F$14 -> 0.34170854 | J10: =$D$20*I10 -> 0.047222222 | K10: =(G10/16)*J10 -> 0.0014756944
C11: =IFERROR(($C$4*F11)/$D$4,"") -> 0 | F11: =IFERROR(D11+E11/16,"") -> 0 | G11: =IFERROR(VLOOKUP(B11,'MP Pan'!$A$6:$F$35,6,FALSE),0) -> 0 | H11: =F11*G11 -> 0 | I11: =F11/$F$14 -> 0 | J11: =$D$20*I11 -> 0 | K11: =(G11/16)*J11 -> 0
C12: =IFERROR(($C$4*F12)/$D$4,"") -> 0 | F12: =IFERROR(D12+E12/16,"") -> 0 | G12: =IFERROR(VLOOKUP(B12,'MP Pan'!$A$6:$F$35,6,FALSE),0) -> 0 | H12: =F12*G12 -> 0 | I12: =F12/$F$14 -> 0 | J12: =$D$20*I12 -> 0 | K12: =(G12/16)*J12 -> 0
C13: =IFERROR(($C$4*F13)/$D$4,"") -> 0 | F13: =IFERROR(D13+E13/16," ") -> 0 | G13: =IFERROR(VLOOKUP(B13,'MP Pan'!$A$6:$F$35,6,FALSE),0) -> 0 | H13: =F13*G13 -> 0 | I13: =F13/$F$14 -> 0 | J13: =$D$20*I13 -> 0 | K13: =(G13/16)*J13 -> 0
B14: Total | D14: =SUM(D4:D13) -> 10 | E14: =SUM(E4:E13) -> 39 | F14: =SUM(F4:F13) -> 12.4375 | G14: =SUM(G4:G13) -> 33.116667 | H14: =SUM(H4:H13) -> 32.525 | I14: =SUM(I4:I13) -> 1 | J14: =$D$20*I14 -> 0.13819444 | K14: =SUM(K4:K13) -> 0.022586806
C16: Con esta fórmiula puedo producir | D16: =24*60 -> 1440 | E16: =_xlfn.CONCAT("Pan ",B2,) -> Pan Manteca 5 libras | G16: Producción Mensual | H16: =D16*30 -> 43200 | J16: =K14*60 -> 1.3552083
C17: PVP | D17: 0.25 | G17: Venta Mensual Q. | H17: =H16*D17 -> 10800
C19: Total de Onzas | D19: =F14*16 -> 199
C20: Onzas por pan | D20: =D19/D16 -> 0.13819444
C22: Costo Total Diario | E22: =H14*1.36 -> 44.234
C23: Venta Total Diaria | E23: =D17*D16 -> 360
C24: Ganancia Diaria | E24: =E23-E22 -> 315.766
C25: % de ganancia | E25: =E24/E22 -> 7.138536

Sheet Manteca
B2: Manteca 5 libras
B3: Materia Prima | C3: Formula % | D3: Libras | E3: Onzas | F3: Conversion (lb) | G3: Costo Q. por Lb o Unidad empeado (Lb X costo Unitario | H3: Costo *Lb | I3: Proporcion de la formula (conversion LB/Total de conversion de ingredientes | J3: Formula para una unidad de (1.01 Onza) | K3: Costo Q por unidad de pan
B4: Harina Suave | C4: 1 | D4: 8 | F4: =IFERROR(D4+E4/16,"") -> 8 | G4: =IFERROR(VLOOKUP(B4,'MP Pan'!$A$6:$F$35,6,FALSE),0) -> 2.85 | H4: =F4*G4 -> 22.8 | I4: =F4/$F$14 -> 0.52459016 | J4: =$D$20*I4 -> 0.41290323 | K4: =(G4/16)*J4 -> 0.073548387
B5: Azucar | C5: =IFERROR(($C$4*F5)/$D$4,"") -> 0.265625 | D5: 2 | E5: 2 | F5: =IFERROR(D5+E5/16,"") -> 2.125 | G5: =IFERROR(VLOOKUP(B5,'MP Pan'!$A$6:$F$35,6,FALSE),0) -> 4.5 | H5: =F5*G5 -> 9.5625 | I5: =F5/$F$14 -> 0.13934426 | J5: =$D$20*I5 -> 0.10967742 | K5: =(G5/16)*J5 -> 0.030846774
B6: Levadura | C6: =IFERROR(($C$4*F6)/$D$4,"") -> 0.03125 | E6: 4 | F6: =IFERROR(D6+E6/16,"") -> 0.25 | G6: =IFERROR(VLOOKUP(B6,'MP Pan'!$A$6:$F$35,6,FALSE),0) -> 11.5 | H6: =F6*G6 -> 2.875 | I6: =F6/$F$14 -> 0.016393443 | J6: =$D$20*I6 -> 0.012903226 | K6: =(G6/16)*J6 -> 0.0092741935
B7: Royal | C7: =IFERROR(($C$4*F7)/$D$4,"") -> 0.046875 | E7: 6 | F7: =IFERROR(D7+E7/16,"") -> 0.375 | G7: =IFERROR(VLOOKUP(B7,'MP Pan'!$A$6:$F$35,6,FALSE),0) -> 4.6 | H7: =F7*G7 -> 1.725 | I7: =F7/$F$14 -> 0.024590164 | J7: =$D$20*I7 -> 0.019354839 | K7: =(G7/16)*J7 -> 0.0055645161
B8: Sal | C8: =IFERROR(($C$4*F8)/$D$4,"") -> 0.0078125 | E8: 1 | F8: =IFERROR(D8+E8/16,"") -> 0.0625 | G8: =IFERROR(VLOOKUP(B8,'MP Pan'!$A$6:$F$35,6,FALSE),0) -> 1.5 | H8: =F8*G8 -> 0.09375 | I8: =F8/$F$14 -> 0.0040983607 | J8: =$D$20*I8 -> 0.0032258065 | K8: =(G8/16)*J8 -> 0.00030241935
B9: Manteca | C9: =IFERROR(($C$4*F9)/$D$4,"") -> 0.1484375 | D9: 1 | E9: 3 | F9: =IFERROR(D9+E9/16,"") -> 1.1875 | G9: =IFERROR(VLOOKUP(B9,'MP Pan'!$A$6:$F$35,6,FALSE),0) -> 7.6666667 | H9: =F9*G9 -> 9.1041667 | I9: =F9/$F$14 -> 0.077868852 | J9: =$D$20*I9 -> 0.061290323 | K9: =(G9/16)*J9 -> 0.02936828
B10: Agua | C10: =IFERROR(($C$4*F10)/$D$4,"") -> 0.40625 | D10: 3 | E10: 4 | F10: =IFERROR(D10+E10/16,"") -> 3.25 | G10: =IFERROR(VLOOKUP(B10,'MP Pan'!$A$6:$F$35,6,FALSE),0) -> 0.5 | H10: =F10*G10 -> 1.625 | I10: =F10/$F$14 -> 0.21311475 | J10: =$D$20*I10 -> 0.16774194 | K10: =(G10/16)*J10 -> 0.0052419355
C11: =IFERROR(($C$4*F11)/$D$4,"") -> 0 | F11: =IFERROR(D11+E11/16,"") -> 0 | G11: =IFERROR(VLOOKUP(B11,'MP Pan'!$A$6:$F$35,6,FALSE),0) -> 0 | H11: =F11*G11 -> 0 | I11: =F11/$F$14 -> 0 | J11: =$D$20*I11 -> 0 | K11: =(G11/16)*J11 -> 0
C12: =IFERROR(($C$4*F12)/$D$4,"") -> 0 | F12: =IFERROR(D12+E12/16,"") -> 0 | G12: =IFERROR(VLOOKUP(B12,'MP Pan'!$A$6:$F$35,6,FALSE),0) -> 0 | H12: =F12*G12 -> 0 | I12: =F12/$F$14 -> 0 | J12: =$D$20*I12 -> 0 | K12: =(G12/16)*J12 -> 0
C13: =IFERROR(($C$4*F13)/$D$4,"") -> 0 | F13: =IFERROR(D13+E13/16," ") -> 0 | G13: =IFERROR(VLOOKUP(B13,'MP Pan'!$A$6:$F$35,6,FALSE),0) -> 0 | H13: =F13*G13 -> 0 | I13: =F13/$F$14 -> 0 | J13: =$D$20*I13 -> 0 | K13: =(G13/16)*J13 -> 0
B14: Total | D14: =SUM(D4:D13) -> 14 | E14: =SUM(E4:E13) -> 20 | F14: =SUM(F4:F13) -> 15.25 | G14: =SUM(G4:G13) -> 33.116667 | H14: =SUM(H4:H13) -> 47.785417 | I14: =SUM(I4:I13) -> 1 | J14: =$D$20*I14 -> 0.78709677 | K14: =SUM(K4:K13) -> 0.15414651
C16: Con esta fórmiula puedo producir | D16: 310 | E16: =_xlfn.CONCAT("Pan ",B2,) -> Pan Manteca 5 libras | G16: Producción Mensual | H16: =D16*30 -> 9300
C17: PVP | D17: 0.33 | G17: Venta Mensual Q. | H17: =H16*D17 -> 3069
C19: Total de Onzas | D19: =F14*16 -> 244
C20: Onzas por pan | D20: =D19/D16 -> 0.78709677
C22: Costo Total Diario | E22: =H14*1.36 -> 64.988167
C23: Venta Total Diaria | E23: =D17*D16 -> 102.3
C24: Ganancia Diaria | E24: =E23-E22 -> 37.311833
C25: % de ganancia | E25: =E24/E22 -> 0.57413273

Sheet Frances
B2: Frances 10 Libras
B3: Materia Prima | C3: Formula % | D3: Libras | E3: Onzas | F3: Conversion (lb) | G3: Costo Q. por Lb o Unidad empeado (Lb X costo Unitario | H3: Costo *Lb | I3: Proporcion de la formula (conversion LB/Total de conversion de ingredientes | J3: Formula para una unidad de (1.01 Onza) | K3: Costo Q por unidad de pan
B4: Harina Dura | C4: 1 | D4: 10 | F4: =IFERROR(D4+E4/16,"") -> 10 | G4: =IFERROR(VLOOKUP(B4,'MP Pan'!$A$6:$F$35,6,FALSE),0) -> 2.85 | H4: =F4*G4 -> 28.5 | I4: =F4/$F$14 -> 0.61068702 | J4: =$D$20*I4 -> 0.50314465 | K4: =(G4/16)*J4 -> 0.089622642
B5: Levadura | C5: =IFERROR(($C$4*F5)/$D$4,"") -> 0.025 | E5: 4 | F5: =IFERROR(D5+E5/16,"") -> 0.25 | G5: =IFERROR(VLOOKUP(B5,'MP Pan'!$A$6:$F$35,6,FALSE),0) -> 11.5 | H5: =F5*G5 -> 2.875 | I5: =F5/$F$14 -> 0.015267176 | J5: =$D$20*I5 -> 0.012578616 | K5: =(G5/16)*J5 -> 0.0090408805
B6: Sal | C6: =IFERROR(($C$4*F6)/$D$4,"") -> 0.0125 | E6: 2 | F6: =IFERROR(D6+E6/16,"") -> 0.125 | G6: =IFERROR(VLOOKUP(B6,'MP Pan'!$A$6:$F$35,6,FALSE),0) -> 1.5 | H6: =F6*G6 -> 0.1875 | I6: =F6/$F$14 -> 0.0076335878 | J6: =$D$20*I6 -> 0.0062893082 | K6: =(G6/16)*J6 -> 0.00058962264
B7: Azucar | C7: =IFERROR(($C$4*F7)/$D$4,"") -> 0.025 | E7: 4 | F7: =IFERROR(D7+E7/16,"") -> 0.25 | G7: =IFERROR(VLOOKUP(B7,'MP Pan'!$A$6:$F$35,6,FALSE),0) -> 4.5 | H7: =F7*G7 -> 1.125 | I7: =F7/$F$14 -> 0.015267176 | J7: =$D$20*I7 -> 0.012578616 | K7: =(G7/16)*J7 -> 0.0035377358
B8: Manteca | C8: =IFERROR(($C$4*F8)/$D$4,"") -> 0.05 | E8: 8 | F8: =IFERROR(D8+E8/16,"") -> 0.5 | G8: =IFERROR(VLOOKUP(B8,'MP Pan'!$A$6:$F$35,6,FALSE),0) -> 7.6666667 | H8: =F8*G8 -> 3.8333333 | I8: =F8/$F$14 -> 0.030534351 | J8: =$D$20*I8 -> 0.025157233 | K8: =(G8/16)*J8 -> 0.012054507
B9: Agua | C9: =IFERROR(($C$4*F9)/$D$4,"") -> 0.525 | D9: 5 | E9: 4 | F9: =IFERROR(D9+E9/16,"") -> 5.25 | G9: =IFERROR(VLOOKUP(B9,'MP Pan'!$A$6:$F$35,6,FALSE),0) -> 0.5 | H9: =F9*G9 -> 2.625 | I9: =F9/$F$14 -> 0.32061069 | J9: =$D$20*I9 -> 0.26415094 | K9: =(G9/16)*J9 -> 0.008254717
C10: =IFERROR(($C$4*F10)/$D$4,"") -> 0 | F10: =IFERROR(D10+E10/16,"") -> 0 | G10: =IFERROR(VLOOKUP(B10,'MP Pan'!$A$6:$F$35,6,FALSE),0) -> 0 | H10: =F10*G10 -> 0 | I10: =F10/$F$14 -> 0 | J10: =$D$20*I10 -> 0 | K10: =(G10/16)*J10 -> 0
C11: =IFERROR(($C$4*F11)/$D$4,"") -> 0 | F11: =IFERROR(D11+E11/16,"") -> 0 | G11: =IFERROR(VLOOKUP(B11,'MP Pan'!$A$6:$F$35,6,FALSE),0) -> 0 | H11: =F11*G11 -> 0 | I11: =F11/$F$14 -> 0 | J11: =$D$20*I11 -> 0 | K11: =(G11/16)*J11 -> 0
C12: =IFERROR(($C$4*F12)/$D$4,"") -> 0 | F12: =IFERROR(D12+E12/16,"") -> 0 | G12: =IFERROR(VLOOKUP(B12,'MP Pan'!$A$6:$F$35,6,FALSE),0) -> 0 | H12: =F12*G12 -> 0 | I12: =F12/$F$14 -> 0 | J12: =$D$20*I12 -> 0 | K12: =(G12/16)*J12 -> 0
C13: =IFERROR(($C$4*F13)/$D$4,"") -> 0 | F13: =IFERROR(D13+E13/16," ") -> 0 | G13: =IFERROR(VLOOKUP(B13,'MP Pan'!$A$6:$F$35,6,FALSE),0) -> 0 | H13: =F13*G13 -> 0 | I13: =F13/$F$14 -> 0 | J13: =$D$20*I13 -> 0 | K13: =(G13/16)*J13 -> 0
B14: Total | D14: =SUM(D4:D13) -> 15 | E14: =SUM(E4:E13) -> 22 | F14: =SUM(F4:F13) -> 16.375 | G14: =SUM(G4:G13) -> 28.516667 | H14: =SUM(H4:H13) -> 39.145833 | I14: =SUM(I4:I13) -> 1 | J14: =$D$20*I14 -> 0.82389937 | K14: =SUM(K4:K13) -> 0.1231001
C16: Con esta fórmiula puedo producir | D16: 318 | E16: =_xlfn.CONCAT("Pan ",B2,) -> Pan Frances 10 Libras | G16: Producción Mensual | H16: =D16*30 -> 9540
C17: PVP | D17: 0.375 | G17: Venta Mensual Q. | H17: =H16*D17 -> 3577.5
C19: Total de Onzas | D19: =F14*16 -> 262
C20: Onzas por pan | D20: =D19/D16 -> 0.82389937
C22: Costo Total Diario | E22: =H14*1.36 -> 53.238333
C23: Venta Total Diaria | E23: =D17*D16 -> 119.25
C24: Ganancia Diaria | E24: =E23-E22 -> 66.011667
C25: % de ganancia | E25: =E24/E22 -> 1.2399274

Sheet Brazo Gitano
B2: Brazo Gitano
B3: Materia Prima | C3: Formula % | D3: Libras | E3: Onzas | F3: Conversion (lb) | G3: Costo Q. por Lb o Unidad empeado (Lb X costo Unitario | H3: Costo *Lb | I3: Proporcion de la formula (conversion LB/Total de conversion de ingredientes | J3: Formula para una unidad de (1.01 Onza) | K3: Costo Q por unidad de pan
B4: huevos | C4: 1 | D4: 15 | F4: =IFERROR(D4+E4/16,"") -> 15 | G4: =IFERROR(VLOOKUP(B4,'MP Pan'!$A$6:$F$35,6,FALSE),0) -> 1.5 | H4: =F4*G4 -> 22.5 | I4: =F4/$F$14 -> 0.86004243 | J4: =$D$20*I4 -> 11.428571 | K4: =(G4/16)*J4 -> 1.0714286
B5: harina suave | C5: =IFERROR(($C$4*F5)/$D$4,"") -> 0.066666667 | D5: 1 | F5: =IFERROR(D5+E5/16,"") -> 1 | G5: =IFERROR(VLOOKUP(B5,'MP Pan'!$A$6:$F$35,6,FALSE),0) -> 2.85 | H5: =F5*G5 -> 2.85 | I5: =F5/$F$14 -> 0.057336162 | J5: =$D$20*I5 -> 0.76190476 | K5: =(G5/16)*J5 -> 0.13571429
B6: aceite | C6: =IFERROR(($C$4*F6)/$D$4,"") -> 0.0041666667 | E6: 1 | F6: =IFERROR(D6+E6/16,"") -> 0.0625 | G6: =IFERROR(VLOOKUP(B6,'MP Pan'!$A$6:$F$35,6,FALSE),0) -> 4 | H6: =F6*G6 -> 0.25 | I6: =F6/$F$14 -> 0.0035835101 | J6: =$D$20*I6 -> 0.047619048 | K6: =(G6/16)*J6 -> 0.011904762
B7: leche | C7: =IFERROR(($C$4*F7)/$D$4,"") -> 0.0044 | D7: 0.066 | F7: =IFERROR(D7+E7/16,"") -> 0.066 | G7: =IFERROR(VLOOKUP(B7,'MP Pan'!$A$6:$F$35,6,FALSE),0) -> 14 | H7: =F7*G7 -> 0.924 | I7: =F7/$F$14 -> 0.0037841867 | J7: =$D$20*I7 -> 0.050285714 | K7: =(G7/16)*J7 -> 0.044
B8: royal | C8: =IFERROR(($C$4*F8)/$D$4,"") -> 0.0083333333 | E8: 2 | F8: =IFERROR(D8+E8/16,"") -> 0.125 | G8: =IFERROR(VLOOKUP(B8,'MP Pan'!$A$6:$F$35,6,FALSE),0) -> 4.6 | H8: =F8*G8 -> 0.575 | I8: =F8/$F$14 -> 0.0071670202 | J8: =$D$20*I8 -> 0.095238095 | K8: =(G8/16)*J8 -> 0.027380952
B9: Agua | C9: =IFERROR(($C$4*F9)/$D$4,"") -> 0 | F9: =IFERROR(D9+E9/16,"") -> 0 | G9: =IFERROR(VLOOKUP(B9,'MP Pan'!$A$6:$F$35,6,FALSE),0) -> 0.5 | H9: =F9*G9 -> 0 | I9: =F9/$F$14 -> 0 | J9: =$D$20*I9 -> 0 | K9: =(G9/16)*J9 -> 0
B10: chantilli | C10: =IFERROR(($C$4*F10)/$D$4,"") -> 0.058333333 | E10: 14 | F10: =IFERROR(D10+E10/16,"") -> 0.875 | G10: =IFERROR(VLOOKUP(B10,'MP Pan'!$A$6:$F$35,6,FALSE),0) -> 0.85714286 | H10: =F10*G10 -> 0.75 | I10: =F10/$F$14 -> 0.050169142 | J10: =$D$20*I10 -> 0.66666667 | K10: =(G10/16)*J10 -> 0.035714286
B11: mermelada | C11: =IFERROR(($C$4*F11)/$D$4,"") -> 0.020833333 | E11: 5 | F11: =IFERROR(D11+E11/16,"") -> 0.3125 | G11: =IFERROR(VLOOKUP(B11,'MP Pan'!$A$6:$F$35,6,FALSE),0) -> 0.71875 | H11: =F11*G11 -> 0.22460938 | I11: =F11/$F$14 -> 0.017917551 | J11: =$D$20*I11 -> 0.23809524 | K11: =(G11/16)*J11 -> 0.010695685
C12: =IFERROR(($C$4*F12)/$D$4,"") -> 0 | F12: =IFERROR(D12+E12/16,"") -> 0 | G12: =IFERROR(VLOOKUP(B12,'MP Pan'!$A$6:$F$35,6,FALSE),0) -> 0 | H12: =F12*G12 -> 0 | I12: =F12/$F$14 -> 0 | J12: =$D$20*I12 -> 0 | K12: =(G12/16)*J12 -> 0
C13: =IFERROR(($C$4*F13)/$D$4,"") -> 0 | F13: =IFERROR(D13+E13/16," ") -> 0 | G13: =IFERROR(VLOOKUP(B13,'MP Pan'!$A$6:$F$35,6,FALSE),0) -> 0 | H13: =F13*G13 -> 0 | I13: =F13/$F$14 -> 0 | J13: =$D$20*I13 -> 0 | K13: =(G13/16)*J13 -> 0
B14: Total | D14: =SUM(D4:D13) -> 16.066 | E14: =SUM(E4:E13) -> 22 | F14: =SUM(F4:F13) -> 17.441 | G14: =SUM(G4:G13) -> 29.025893 | H14: =SUM(H4:H13) -> 28.073609 | I14: =SUM(I4:I13) -> 1 | J14: =$D$20*I14 -> 13.288381 | K14: =SUM(K4:K13) -> 1.3368385
C16: Con esta fórmiula puedo producir | D16: 21 | E16: =_xlfn.CONCAT("Pan ",B2,) -> Pan Brazo Gitano | G16: Producción Mensual | H16: =D16*30 -> 630
C17: PVP | D17: 4 | G17: Venta Mensual Q. | H17: =H16*D17 -> 2520
C19: Total de Onzas | D19: =F14*16 -> 279.056
C20: Onzas por pan | D20: =D19/D16 -> 13.288381
C22: Costo Total Diario | E22: =H14 -> 28.073609
C23: Venta Total Diaria | E23: =D17*D16 -> 84
C24: Ganancia Diaria | E24: =E23-E22 -> 55.926391
C25: % de ganancia | E25: =E24/E22 -> 1.992134

Sheet Torta
B2: Pan frances tipo torta
B3: Materia Prima | C3: Formula % | D3: Libras | E3: Onzas | F3: Conversion (lb) | G3: Costo Q. por Lb o Unidad empeado (Lb X costo Unitario | H3: Costo *Lb | I3: Proporcion de la formula (conversion LB/Total de conversion de ingredientes | J3: Formula para una unidad de (1.01 Onza) | K3: Costo Q por unidad de pan
B4: Harina Dura | C4: 1 | D4: 2.5 | F4: =IFERROR(D4+E4/16,"") -> 2.5 | G4: =IFERROR(VLOOKUP(B4,'MP Pan'!$A$6:$F$35,6,FALSE),0) -> 2.85 | H4: =F4*G4 -> 7.125 | I4: =F4/$F$14 -> 0.46783626 | J4: =$D$20*I4 -> 1.4814815 | K4: =(G4/16)*J4 -> 0.26388889
B5: Levadura | C5: =IFERROR(($C$4*F5)/$D$4,"") -> 0.025 | E5: 1 | F5: =IFERROR(D5+E5/16,"") -> 0.0625 | G5: =IFERROR(VLOOKUP(B5,'MP Pan'!$A$6:$F$35,6,FALSE),0) -> 11.5 | H5: =F5*G5 -> 0.71875 | I5: =F5/$F$14 -> 0.011695906 | J5: =$D$20*I5 -> 0.037037037 | K5: =(G5/16)*J5 -> 0.02662037
B6: Sal | C6: =IFERROR(($C$4*F6)/$D$4,"") -> 0.0125 | E6: 0.5 | F6: =IFERROR(D6+E6/16,"") -> 0.03125 | G6: =IFERROR(VLOOKUP(B6,'MP Pan'!$A$6:$F$35,6,FALSE),0) -> 1.5 | H6: =F6*G6 -> 0.046875 | I6: =F6/$F$14 -> 0.0058479532 | J6: =$D$20*I6 -> 0.018518519 | K6: =(G6/16)*J6 -> 0.0017361111
B7: Azucar | C7: =IFERROR(($C$4*F7)/$D$4,"") -> 0.075 | E7: 3 | F7: =IFERROR(D7+E7/16,"") -> 0.1875 | G7: =IFERROR(VLOOKUP(B7,'MP Pan'!$A$6:$F$35,6,FALSE),0) -> 4.5 | H7: =F7*G7 -> 0.84375 | I7: =F7/$F$14 -> 0.035087719 | J7: =$D$20*I7 -> 0.11111111 | K7: =(G7/16)*J7 -> 0.03125
B8: Manteca | C8: =IFERROR(($C$4*F8)/$D$4,"") -> 0.1 | E8: 4 | F8: =IFERROR(D8+E8/16,"") -> 0.25 | G8: =IFERROR(VLOOKUP(B8,'MP Pan'!$A$6:$F$35,6,FALSE),0) -> 7.6666667 | H8: =F8*G8 -> 1.9166667 | I8: =F8/$F$14 -> 0.046783626 | J8: =$D$20*I8 -> 0.14814815 | K8: =(G8/16)*J8 -> 0.070987654
B9: Agua | C9: =IFERROR(($C$4*F9)/$D$4,"") -> 0.9 | D9: 2 | E9: 4 | F9: =IFERROR(D9+E9/16,"") -> 2.25 | G9: =IFERROR(VLOOKUP(B9,'MP Pan'!$A$6:$F$35,6,FALSE),0) -> 0.5 | H9: =F9*G9 -> 1.125 | I9: =F9/$F$14 -> 0.42105263 | J9: =$D$20*I9 -> 1.3333333 | K9: =(G9/16)*J9 -> 0.041666667
B10: leche | C10: =IFERROR(($C$4*F10)/$D$4,"") -> 0.025 | E10: 1 | F10: =IFERROR(D10+E10/16,"") -> 0.0625 | G10: =IFERROR(VLOOKUP(B10,'MP Pan'!$A$6:$F$35,6,FALSE),0) -> 14 | H10: =F10*G10 -> 0.875 | I10: =F10/$F$14 -> 0.011695906 | J10: =$D$20*I10 -> 0.037037037 | K10: =(G10/16)*J10 -> 0.032407407
C11: =IFERROR(($C$4*F11)/$D$4,"") -> 0 | F11: =IFERROR(D11+E11/16,"") -> 0 | G11: =IFERROR(VLOOKUP(B11,'MP Pan'!$A$6:$F$35,6,FALSE),0) -> 0 | H11: =F11*G11 -> 0 | I11: =F11/$F$14 -> 0 | J11: =$D$20*I11 -> 0 | K11: =(G11/16)*J11 -> 0
C12: =IFERROR(($C$4*F12)/$D$4,"") -> 0 | F12: =IFERROR(D12+E12/16,"") -> 0 | G12: =IFERROR(VLOOKUP(B12,'MP Pan'!$A$6:$F$35,6,FALSE),0) -> 0 | H12: =F12*G12 -> 0 | I12: =F12/$F$14 -> 0 | J12: =$D$20*I12 -> 0 | K12: =(G12/16)*J12 -> 0
C13: =IFERROR(($C$4*F13)/$D$4,"") -> 0 | F13: =IFERROR(D13+E13/16," ") -> 0 | G13: =IFERROR(VLOOKUP(B13,'MP Pan'!$A$6:$F$35,6,FALSE),0) -> 0 | H13: =F13*G13 -> 0 | I13: =F13/$F$14 -> 0 | J13: =$D$20*I13 -> 0 | K13: =(G13/16)*J13 -> 0
B14: Total | D14: =SUM(D4:D13) -> 4.5 | E14: =SUM(E4:E13) -> 13.5 | F14: =SUM(F4:F13) -> 5.34375 | G14: =SUM(G4:G13) -> 42.516667 | H14: =SUM(H4:H13) -> 12.651042 | I14: =SUM(I4:I13) -> 1 | J14: =$D$20*I14 -> 3.1666667 | K14: =SUM(K4:K13) -> 0.4685571
C16: Con esta fórmiula puedo producir | D16: 27 | E16: =_xlfn.CONCAT("Pan ",B2,) -> Pan Pan frances tipo torta | G16: Producción Mensual | H16: =D16*30 -> 810
C17: PVP | D17: 0.375 | G17: Venta Mensual Q. | H17: =H16*D17 -> 303.75
C19: Total de Onzas | D19: =F14*16 -> 85.5
C20: Onzas por pan | D20: =D19/D16 -> 3.1666667
C22: Costo Total Diario | E22: =H14 -> 12.651042
C23: Venta Total Diaria | E23: =D17*D16 -> 10.125
C24: Ganancia Diaria | E24: =E23-E22 -> -2.5260417
C25: % de ganancia | E25: =E24/E22 -> -0.19967065

Sheet Cubilites
B2: Cubilites de Banano
B3: Materia Prima | C3: Formula % | D3: Libras | E3: Onzas | F3: Conversion (lb) | G3: Costo Q. por Lb o Unidad empeado (Lb X costo Unitario | H3: Costo *Lb | I3: Proporcion de la formula (conversion LB/Total de conversion de ingredientes | J3: Formula para una unidad de (1.01 Onza) | K3: Costo Q por unidad de pan
B4: Harina suave | C4: 1 | D4: 4 | F4: =IFERROR(D4+E4/16,"") -> 4 | G4: =IFERROR(VLOOKUP(B4,'MP Pan'!$A$6:$F$35,6,FALSE),0) -> 2.85 | H4: =F4*G4 -> 11.4 | I4: =F4/$F$14 -> 0.15005862 | J4: =$D$20*I4 -> 1.1428571 | K4: =(G4/16)*J4 -> 0.20357143
B5: Levadura | C5: =IFERROR(($C$4*F5)/$D$4,"") -> 0.03125 | E5: 2 | F5: =IFERROR(D5+E5/16,"") -> 0.125 | G5: =IFERROR(VLOOKUP(B5,'MP Pan'!$A$6:$F$35,6,FALSE),0) -> 11.5 | H5: =F5*G5 -> 1.4375 | I5: =F5/$F$14 -> 0.0046893318 | J5: =$D$20*I5 -> 0.035714286 | K5: =(G5/16)*J5 -> 0.025669643
B6: Sal | C6: =IFERROR(($C$4*F6)/$D$4,"") -> 0.0078125 | E6: 0.5 | F6: =IFERROR(D6+E6/16,"") -> 0.03125 | G6: =IFERROR(VLOOKUP(B6,'MP Pan'!$A$6:$F$35,6,FALSE),0) -> 1.5 | H6: =F6*G6 -> 0.046875 | I6: =F6/$F$14 -> 0.0011723329 | J6: =$D$20*I6 -> 0.0089285714 | K6: =(G6/16)*J6 -> 0.00083705357
B7: Azucar | C7: =IFERROR(($C$4*F7)/$D$4,"") -> 1 | D7: 4 | F7: =IFERROR(D7+E7/16,"") -> 4 | G7: =IFERROR(VLOOKUP(B7,'MP Pan'!$A$6:$F$35,6,FALSE),0) -> 4.5 | H7: =F7*G7 -> 18 | I7: =F7/$F$14 -> 0.15005862 | J7: =$D$20*I7 -> 1.1428571 | K7: =(G7/16)*J7 -> 0.32142857
